Workbook

Sheet Participantes y pagos
D3: Participante | E3: Pago
D4: Michael Letrado | E4: OK
D5: Sergio Echeverria | E5: OK
D6: Gabriel Letrado | E6: OK
D7: Javier Adames
D8: Sebastian Rios | E8: OK
D9: Karen Vargas | E9: OK
D10: Monica Marin | E10: OK
D11: Cesar Letrado | E11: OK
D12: Kevin Ravelo | E12: OK
D13: Mateo Salamanca | E13: OK
D14: Esmeralda Rueda
D15: Julian Rodriguez | E15: OK
D16: Diego Marin | E16: OK
D17: Samuel Ramirez | E17: OK
D18: Cristian Godoy | E18: OK
D19: Peter Letrado | E19: OK
D20: Nicolas Letrado | E20: OK
D21: Orlando Narvaez | E21: OK
D22: Andres Castro | E22: OK
D23: Fredy Hernandez | E23: OK
D24: Sneyder Bonilla | E24: OK
D25: Yury Romero | E25: OK
D26: Juan Moreno | E26: OK
... D34: Deivid Ramirez | E34: OK
D35: Fredy Letrado

Sheet Pronosticos Iniciales
C2: Participante | D2: Campeon | E2: Goleador | F2: Mvp | G2: Maximo asistente | H2: Goleador F. Grupos | I2: Mejor Equipo Grupos | J2: Puntos obtenidos | K2: Puntos Posibles
C3: Michael Letrado | D3: Francia | E3: Mbappe | F3: Mbappe | G3: Bruno Fernandez | H3: Cristiano Ronaldo | I3: Belgica
C4: Sergio Echeverria | D4: Francia | E4: Luis Suarez | F4: Luis Diaz | G4: James Rodriguez | H4: Luis Diaz | I4: Colombia
C5: Gabriel Letrado | D5: Francia | E5: Harry Kane | F5: Mbappe | G5: Yamal | H5: Mbappe | I5: Argentina
C6: Javier Adames | D6: España | E6: Mbappe | F6: Olise | G6: Yamal | H6: Mbappe | I6: España
C7: Sebastian Rios | D7: Francia | E7: Mbappe | F7: Mbappe | G7: Musiala | H7: Cristiano Ronaldo | I7: España
C8: Karen Vargas | D8: España | E8: Mbappe | F8: Yamal | G8: Yamal | H8: Mbappe | I8: España
C9: Monica Marin | D9: España | E9: Harry Kane | F9: Yamal | G9: Yamal | H9: Harry Kane | I9: Argentina
C10: Cesar Letrado | D10: España | E10: Mbappe | F10: Yamal | G10: Yamal | H10: Mbappe | I10: España
C11: Kevin Ravelo | D11: Francia | E11: Mbappe | F11: Yamal | G11: Yamal | H11: Harry Kane | I11: Argentina
C12: Mateo Salamanca | D12: España | E12: Harry Kane | F12: Yamal | G12: Pedri | H12: Julian Alvarez | I12: Argentina
C13: Esmeralda Rueda | D13: España | E13: Harry Kane | F13: Yamal | G13: Yamal | H13: Lautaro Martinez | I13: Argentina
C14: Julian Rodriguez | D14: Brasil | E14: Haaland | F14: Raphina | G14: James Rodriguez | H14: Lautaro Martinez | I14: Brasil
... C34: Fredy Letrado | D34: Argentina | E34: Mbappe | F34: Messi | G34: Messi | H34: Mbappe | I34: Francia

Sheet RESULTADOS
A1: Participante | B1: Partido 1 | D1: Resultado Oficial | F1: Partido 2 | H1: Resultado Oficial | J1: Puntaje de la jornada | K1: Partido 3 | M1: Resultado Oficial | O1: Partido 4 | Q1: Resultado Oficial | S1: Puntaje de la jornada | T1: Partido 5 | V1: Resultado Oficial | X1: Partido 6 | Z1: Resultado Oficial | AB1: Partido 7 | AD1: Resultado Oficial | AF1: Partido 8 | AH1: Resultado Oficial | AJ1: Puntaje de la jornada | AK1: Partido | AM1: Resultado Oficial | AO1: Partido | AQ1: Resultado Oficial | AS1: Partido | AU1: Resultado Oficial | AW1: Partido 12 | AY1: Resultado Oficial | BA1: Puntaje de la jornada | BB1: Partido | BD1: Resultado Oficial | BF1: Partido | BH1: Resultado Oficial | BJ1: Partido | BL1: Resultado Oficial | BN1: Partido 16 | BP1: Resultado Oficial | BR1: Puntaje de la jornada | BS1: Partido | BU1: Resultado Oficial | BW1: Partido | BY1: Resultado Oficial | CA1: Partido | CC1: Resultado Oficial | CE1: Partido 20 | CG1: Resultado Oficial | CI1: Puntaje de la jornada | CJ1: Partido 21 | CL1: Resultado Oficial | CN1: Partido 22 | CP1: Resultado Oficial | CR1: Partido 23 | CT1: Resultado Oficial | CV1: Partido 24 | CX1: Resultado Oficial | CZ1: Puntaje de la jornada | DA1: Partido 25 | DC1: Resultado Oficial | DE1: Partido 26 | DG1: Resultado Oficial | DI1: Partido 27 | DK1: Resultado Oficial | DM1: Partido 28 | DO1: Resultado Oficial | DQ1: Puntaje de la jornada | DR1: Partido 29 | DT1: Resultado Oficial | DV1: Partido 30 | DX1: Resultado Oficial | DZ1: Partido 31 | EB1: Resultado Oficial | ED1: Partido 32 | EF1: Resultado Oficial | EH1: Puntaje de la jornada | EI1: Partido 33 | EK1: Resultado Oficial | EM1: Partido 34 | EO1: Resultado Oficial | EQ1: Partido 35 | ES1: Resultado Oficial | EU1: Partido 36 | EW1: Resultado Oficial | EY1: Puntaje de la jornada | EZ1: Partido 37 | FB1: Resultado Oficial | FD1: Partido 38 | FF1: Resultado Oficial | FH1: Partido 39 | FJ1: Resultado Oficial | FL1: Partido 40 | FN1: Resultado Oficial | FP1: Puntaje de la jornada | FQ1: Partido | FS1: Resultado Oficial | FU1: Partido | FW1: Resultado Oficial | FY1: Partido | GA1: Resultado Oficial | GC1: Partido 44 | GE1: Resultado Oficial | GG1: Puntaje de la jornada | GH1: Partido | GJ1: Resultado Oficial | GL1: Partido | GN1: Resultado Oficial | GP1: Partido | GR1: Resultado Oficial | GT1: Partido 48 | GV1: Resultado Oficial | GX1: Puntaje de la jornada | GY1: Partido | HA1: Resultado Oficial | HC1: Partido | HE1: Resultado Oficial | HG1: Partido | HI1: Resultado Oficial | HK1: Partido | HM1: Resultado Oficial | HO1: Partido | HQ1: Resultado Oficial | HS1: Partido 54 | HU1: Resultado Oficial | HW1: Puntaje de la jornada | HX1: Partido | HZ1: Resultado Oficial | IB1: Partido | ID1: Resultado Oficial | IF1: Partido | IH1: Resultado Oficial | IJ1: Partido | IL1: Resultado Oficial | IN1: Partido | IP1: Resultado Oficial | IR1: Partido 60 | IT1: Resultado Oficial | IV1: Puntaje de la jornada | IW1: Partido | IY1: Resultado Oficial | JA1: Partido | JC1: Resultado Oficial | JE1: Partido | JG1: Resultado Oficial | JI1: Partido | JK1: Resultado Oficial | JM1: Partido | JO1: Resultado Oficial | JQ1: Partido 66 | JS1: Resultado Oficial | JU1: Puntaje de la jornada | JV1: Partido | JX1: Resultado Oficial | JZ1: Partido | KB1: Resultado Oficial | KD1: Partido | KF1: Resultado Oficial | KH1: Partido | KJ1: Resultado Oficial | KL1: Partido | KN1: Resultado Oficial | KP1: Partido 72 | KR1: Resultado Oficial | KT1: Puntaje de la jornada | KU1: Partido 73 | KW1: Resultado Oficial | KY1: Puntaje de la jornada | KZ1: Partido | LB1: Resultado Oficial | LD1: Partido | LF1: Resultado Oficial | LH1: Partido 76 | LJ1: Resultado Oficial | LL1: Puntaje de la jornada | LM1: Partido | LO1: Resultado Oficial | LQ1: Partido | LS1: Resultado Oficial | LU1: Partido 79 | LW1: Resultado Oficial | LY1: Puntaje de la jornada | LZ1: Partido | MB1: Resultado Oficial | MD1: Partido | MF1: Resultado Oficial | MH1: Partido 82 | MJ1: Resultado Oficial | ML1: Puntaje de la jornada | MM1: Partido | MO1: Resultado Oficial | MQ1: Partido | MS1: Resultado Oficial | MU1: Partido 85 | MW1: Resultado Oficial | MY1: Puntaje de la jornada | MZ1: Partido | NB1: Resultado Oficial | ND1: Partido | NF1: Resultado Oficial | NH1: Partido 88 | NJ1: Resultado Oficial | NL1: Puntaje de la jornada | NM1: Partido | NO1: Resultado Oficial | NQ1: Partido 90 | NS1: Resultado Oficial | NU1: Puntaje de la jornada | NV1: Partido | NX1: Resultado Oficial | NZ1: Partido 92 | OB1: Resultado Oficial | OD1: Puntaje de la jornada | OE1: Partido | OG1: Resultado Oficial | OI1: Partido 94 | OK1: Resultado Oficial | OM1: Puntaje de la jornada | ON1: Partido | OP1: Resultado Oficial | OR1: Partido 96 | OT1: Resultado Oficial | OV1: Puntaje de la jornada | OW1: Partido 97 | OY1: Resultado Oficial | PA1: Puntaje de la jornada | PB1: Partido 98 | PD1: Resultado Oficial | PF1: Puntaje de la jornada | PG1: Partido | PI1: Resultado Oficial | PK1: Partido 100 | PM1: Resultado Oficial | PO1: Puntaje de la jornada | PP1: Partido | PR1: Resultado Oficial | PT1: Puntaje de la jornada | PU1: Partido 102 | PW1: Resultado Oficial | PY1: Puntaje de la jornada | PZ1: Partido 103 | QB1: Resultado Oficial | QD1: Puntaje de la jornada | QE1: Partido 104 | QG1: Resultado Oficial | QI1: Puntaje de la jornada
D2: 2 | E2: 0 | H2: 2 | I2: 1 | M2: 1 | N2: 1 | Q2: 4 | R2: 1 | V2: 1 | W2: 1 | Z2: 1 | AA2: 1 | AD2: 0 | AE2: 1 | AH2: 2 | AI2: 0 | AM2: 7 | AN2: 1 | AQ2: 2 | AR2: 2 | AU2: 1 | AV2: 0 | AY2: 5 | AZ2: 1 | BD2: 0 | BE2: 0 | BH2: 1 | BI2: 1 | BL2: 1 | BM2: 1 | BP2: 2 | BQ2: 2 | BU2: 3 | BV2: 1 | BY2: 1 | BZ2: 4 | CC2: 3 | CD2: 0 | CG2: 3 | CH2: 1 | CL2: 1 | CM2: 1 | CP2: 4 | CQ2: 2 | CT2: 1 | CU2: 0 | CX2: 1 | CY2: 3 | DC2: 1 | DD2: 1 | DG2: 4 | DH2: 1 | DK2: 6 | DL2: 0 | DO2: 1 | DP2: 0 | DT2: 2 | DU2: 0 | DX2: 0 | DY2: 1 | EB2: 3 | EC2: 0 | EF2: 0 | EG2: 1 | EK2: 5 | EL2: 1 | EO2: 2 | EP2: 1 | ES2: 0 | ET2: 0 | EW2: 0 | EX2: 4
B3: Mexico | C3: Sudafrica | D3: Puntos | F3: Corea | G3: R. Checa | H3: Puntos | K3: Canada | L3: Boznia | M3: Puntos | O3: EEUU | P3: Paraguay | Q3: Puntos | T3: Catar | U3: Suiza | V3: Puntos | X3: Brasil | Y3: Marruecos | Z3: Puntos | AB3: Haiti | AC3: Escocia | AD3: Puntos | AF3: Australia | AG3: Turquía | AH3: Puntos | AK3: Alemania | AL3: Curazao | AM3: Puntos | AO3: Países bajos | AP3: Japon | AQ3: Puntos | AS3: Costa de marfil | AT3: Ecuador | AU3: Puntos | AW3: Suecia | AX3: Túnez | AY3: Puntos | BB3: España | BC3: Cabo Verde | BD3: Puntos | BF3: Belgica | BG3: Egipto | BH3: Puntos | BJ3: Arabia Saudí | BK3: Uruguay | BL3: Puntos | BN3: Iran | BO3: Nueva Zelanda | BP3: Puntos | BS3: Francia | BT3: Senegal | BU3: Puntos | BW3: Iraq | BX3: Noruega | BY3: Puntos | CA3: Argentina | CB3: Argelia | CC3: Puntos | CE3: Austria | CF3: Jordania | CG3: Puntos | CJ3: Portugal | CK3: RD Congo | CL3: Puntos | CN3: Inlgaterra | CO3: Croacia | CP3: Puntos | CR3: Ghana | CS3: Panamá | CT3: Puntos | CV3: Usbekistan | CW3: Colombia | CX3: Puntos | DA3: R. Checa | DB3: Sudáfrica | DC3: Puntos | DE3: Suiza | DF3: Bosnia | DG3: Puntos | DI3: Canadá | DJ3: Catar | DK3: Puntos | DM3: Mexico | DN3: Corea | DO3: Puntos | DR3: EEUU | DS3: Australia | DT3: Puntos | DV3: Escocia | DW3: Marruecos | DX3: Puntos | DZ3: Brasil | EA3: Haiti | EB3: Puntos | ED3: Turquia | EE3: Paraguay | EF3: Puntos | EI3: Países bajos | EJ3: Suecia | EK3: Puntos | EM3: Alemania | EN3: Costa de marfil | EO3: Puntos | EQ3: Ecuador | ER3: Curazao | ES3: Puntos | EU3: Túnez | EV3: Japón | EW3: Puntos | EZ3: España | FA3: Arabia Saudí | FB3: Puntos | FD3: Belgica | FE3: Iran | FF3: Puntos | FH3: Uruguay | FI3: Cabo verde | FJ3: Puntos | FL3: Nueva Zelanda | FM3: Egipto | FN3: Puntos | FS3: Puntos | FW3: Puntos | GA3: Puntos | GE3: Puntos | GJ3: Puntos | GN3: Puntos | GR3: Puntos | GV3: Puntos | HA3: Puntos | HE3: Puntos | HI3: Puntos | HM3: Puntos | HQ3: Puntos | HU3: Puntos | HZ3: Puntos | ID3: Puntos | IH3: Puntos | IL3: Puntos | IP3: Puntos | IT3: Puntos | IY3: Puntos | JC3: Puntos | JG3: Puntos | JK3: Puntos | JO3: Puntos | JS3: Puntos | JX3: Puntos | KB3: Puntos | KF3: Puntos | KJ3: Puntos | KN3: Puntos | KR3: Puntos | KW3: Puntos | LB3: Puntos | LF3: Puntos | LJ3: Puntos | LO3: Puntos | LS3: Puntos | LW3: Puntos | MB3: Puntos | MF3: Puntos | MJ3: Puntos | MO3: Puntos | MS3: Puntos | MW3: Puntos | NB3: Puntos | NF3: Puntos | NJ3: Puntos | NO3: Puntos | NS3: Puntos | NX3: Puntos | OB3: Puntos | OG3: Puntos | OK3: Puntos | OP3: Puntos | OT3: Puntos | OY3: Puntos | PD3: Puntos | PI3: Puntos | PM3: Puntos | PR3: Puntos | PW3: Puntos | QB3: Puntos | QG3: Puntos
A4: Michael Letrado | B4: 2 | C4: 0 | D4: =IF( AND(B4=$D$2, C4=$E$2), 5, IF( AND( SIGN(B4-C4)=SIGN($D$2-$E$2), OR(B4=$D$2, C4=$E$2) ), 4, IF( SIGN(B4-C4)=SIGN($D$2-$E$2), 3, IF( OR(B4=$D$2, C4=$E$2), 1, 0 ) ) )) -> 5 | F4: 1 | G4: 1 | H4: =IF( AND(F4=$H$2, G4=$I$2), 5, IF( AND( SIGN(F4-G4)=SIGN($H$2-$I$2), OR(F4=$H$2, G4=$I$2) ), 4, IF( SIGN(F4-G4)=SIGN($H$2-$I$2), 3, IF( OR(F4=$H$2, G4=$I$2), 1, 0 ) ) )) -> 1 | J4: =D4+H4 -> 6 | K4: 2 | L4: 1 | M4: =IF(AND(K4="",L4=""),0,IF(AND(K4=$M$2,L4=$N$2),5,IF(AND(SIGN(K4-L4)=SIGN($M$2-$N$2),OR(K4=$M$2,L4=$N$2)),4,IF(SIGN(K4-L4)=SIGN($M$2-$N$2),3,IF(OR(K4=$M$2,L4=$N$2),1,0))))) -> 1 | O4: 1 | P4: 2 | Q4: =IF(AND(O4="",P4=""),0,IF(AND(O4=$Q$2,P4=$R$2),5,IF(AND(SIGN(O4-P4)=SIGN($Q$2-$R$2),OR(O4=$Q$2,P4=$R$2)),4,IF(SIGN(O4-P4)=SIGN($Q$2-$R$2),3,IF(OR(O4=$Q$2,P4=$R$2),1,0))))) -> 0 | S4: =M4+Q4 -> 1 | T4: 0 | U4: 3 | V4: =IF(AND(T4="",U4=""),0,IF(AND(T4=$V$2,U4=$W$2),5,IF(AND(SIGN(T4-U4)=SIGN($V$2-$W$2),OR(T4=$V$2,U4=$W$2)),4,IF(SIGN(T4-U4)=SIGN($V$2-$W$2),3,IF(OR(T4=$V$2,U4=$W$2),1,0))))) -> 0 | X4: 2 | Y4: 2 | Z4: =IF(AND(X4="",Y4=""),0,IF(AND(X4=$Z$2,Y4=$AA$2),5,IF(AND(SIGN(X4-Y4)=SIGN($Z$2-$AA$2),OR(X4=$Z$2,Y4=$AA$2)),4,IF(SIGN(X4-Y4)=SIGN($Z$2-$AA$2),3,IF(OR(X4=$Z$2,Y4=$AA$2),1,0))))) -> 3 | AB4: 0 | AC4: 2 | AD4: =IF(AND(AB4="",AC4=""),0,IF(AND(AB4=$AD$2,AC4=$AE$2),5,IF(AND(SIGN(AB4-AC4)=SIGN($AD$2-$AE$2),OR(AB4=$AD$2,AC4=$AE$2)),4,IF(SIGN(AB4-AC4)=SIGN($AD$2-$AE$2),3,IF(OR(AB4=$AD$2,AC4=$AE$2),1,0))))) -> 4 | AF4: 1 | AG4: 2 | AH4: =IF(AND(AF4="",AG4=""),0,IF(AND(AF4=$AH$2,AG4=$AI$2),5,IF(AND(SIGN(AF4-AG4)=SIGN($AH$2-$AI$2),OR(AF4=$AH$2,AG4=$AI$2)),4,IF(SIGN(AF4-AG4)=SIGN($AH$2-$AI$2),3,IF(OR(AF4=$AH$2,AG4=$AI$2),1,0))))) -> 0 | AJ4: =V4+Z4+AD4+AH4 -> 7 | AK4: 5 | AL4: 0 | AM4: =IF(AND(AK4="",AL4=""),0,IF(AND(AK4=$AM$2,AL4=$AN$2),5,IF(AND(SIGN(AK4-AL4)=SIGN($AM$2-$AN$2),OR(AK4=$AM$2,AL4=$AN$2)),4,IF(SIGN(AK4-AL4)=SIGN($AM$2-$AN$2),3,IF(OR(AK4=$AM$2,AL4=$AN$2),1,0))))) -> 3 | AO4: 1 | AP4: 2 | AQ4: =IF(AND(AO4="",AP4=""),0,IF(AND(AO4=$AQ$2,AP4=$AR$2),5,IF(AND(SIGN(AO4-AP4)=SIGN($AQ$2-$AR$2),OR(AO4=$AQ$2,AP4=$AR$2)),4,IF(SIGN(AO4-AP4)=SIGN($AQ$2-$AR$2),3,IF(OR(AO4=$AQ$2,AP4=$AR$2),1,0))))) -> 1 | AS4: 1 | AT4: 2 | AU4: =IF(AND(AS4="",AT4=""),0,IF(AND(AS4=$AU$2,AT4=$AV$2),5,IF(AND(SIGN(AS4-AT4)=SIGN($AU$2-$AV$2),OR(AS4=$AU$2,AT4=$AV$2)),4,IF(SIGN(AS4-AT4)=SIGN($AU$2-$AV$2),3,IF(OR(AS4=$AU$2,AT4=$AV$2),1,0))))) -> 1 | AW4: 2 | AX4: 0 | AY4: =IF(AND(AW4="",AX4=""),0,IF(AND(AW4=$AY$2,AX4=$AZ$2),5,IF(AND(SIGN(AW4-AX4)=SIGN($AY$2-$AZ$2),OR(AW4=$AY$2,AX4=$AZ$2)),4,IF(SIGN(AW4-AX4)=SIGN($AY$2-$AZ$2),3,IF(OR(AW4=$AY$2,AX4=$AZ$2),1,0))))) -> 3 | BA4: =AM4+AQ4+AU4+AY4 -> 8 | BB4: 7 | BC4: 0 | BD4: =IF(AND(BB4="",BC4=""),0,IF(AND(BB4=$BD$2,BC4=$BE$2),5,IF(AND(SIGN(BB4-BC4)=SIGN($BD$2-$BE$2),OR(BB4=$BD$2,BC4=$BE$2)),4,IF(SIGN(BB4-BC4)=SIGN($BD$2-$BE$2),3,IF(OR(BB4=$BD$2,BC4=$BE$2),1,0))))) -> 1 | BF4: 3 | BG4: 1 | BH4: =IF(AND(BF4="",BG4=""),0,IF(AND(BF4=$BH$2,BG4=$BI$2),5,IF(AND(SIGN(BF4-BG4)=SIGN($BH$2-$BI$2),OR(BF4=$BH$2,BG4=$BI$2)),4,IF(SIGN(BF4-BG4)=SIGN($BH$2-$BI$2),3,IF(OR(BF4=$BH$2,BG4=$BI$2),1,0))))) -> 1 | BJ4: 0 | BK4: 2 | BL4: =IF(AND(BJ4="",BK4=""),0,IF(AND(BJ4=$BL$2,BK4=$BM$2),5,IF(AND(SIGN(BJ4-BK4)=SIGN($BL$2-$BM$2),OR(BJ4=$BL$2,BK4=$BM$2)),4,IF(SIGN(BJ4-BK4)=SIGN($BL$2-$BM$2),3,IF(OR(BJ4=$BL$2,BK4=$BM$2),1,0))))) -> 0 | BN4: 2 | BO4: 1 | BP4: =IF(AND(BN4="",BO4=""),0,IF(AND(BN4=$BP$2,BO4=$BQ$2),5,IF(AND(SIGN(BN4-BO4)=SIGN($BP$2-$BQ$2),OR(BN4=$BP$2,BO4=$BQ$2)),4,IF(SIGN(BN4-BO4)=SIGN($BP$2-$BQ$2),3,IF(OR(BN4=$BP$2,BO4=$BQ$2),1,0))))) -> 1 | BR4: =BD4+BH4+BL4+BP4 -> 3 | BS4: 2 | BT4: 1 | BU4: =IF(AND(BS4="",BT4=""),0,IF(AND(BS4=$BU$2,BT4=$BV$2),5,IF(AND(SIGN(BS4-BT4)=SIGN($BU$2-$BV$2),OR(BS4=$BU$2,BT4=$BV$2)),4,IF(SIGN(BS4-BT4)=SIGN($BU$2-$BV$2),3,IF(OR(BS4=$BU$2,BT4=$BV$2),1,0))))) -> 4 | BW4: 0 | BX4: 2 | BY4: =IF(AND(BW4="",BX4=""),0,IF(AND(BW4=$BY$2,BX4=$BZ$2),5,IF(AND(SIGN(BW4-BX4)=SIGN($BY$2-$BZ$2),OR(BW4=$BY$2,BX4=$BZ$2)),4,IF(SIGN(BW4-BX4)=SIGN($BY$2-$BZ$2),3,IF(OR(BW4=$BY$2,BX4=$BZ$2),1,0))))) -> 3 | CA4: 2 | CB4: 1 | CC4: =IF(AND(CA4="",CB4=""),0,IF(AND(CA4=$CC$2,CB4=$CD$2),5,IF(AND(SIGN(CA4-CB4)=SIGN($CC$2-$CD$2),OR(CA4=$CC$2,CB4=$CD$2)),4,IF(SIGN(CA4-CB4)=SIGN($CC$2-$CD$2),3,IF(OR(CA4=$CC$2,CB4=$CD$2),1,0))))) -> 3 | CE4: 2 | CF4: 0 | CG4: =IF(AND(CE4="",CF4=""),0,IF(AND(CE4=$CG$2,CF4=$CH$2),5,IF(AND(SIGN(CE4-CF4)=SIGN($CG$2-$CH$2),OR(CE4=$CG$2,CF4=$CH$2)),4,IF(SIGN(CE4-CF4)=SIGN($CG$2-$CH$2),3,IF(OR(CE4=$CG$2,CF4=$CH$2),1,0))))) -> 3 | CI4: =BU4+BY4+CC4+CG4 -> 13 | CJ4: 4 | CK4: 0 | CL4: =IF(AND(CJ4="",CK4=""),0,IF(AND(CJ4=$CL$2,CK4=$CM$2),5,IF(AND(SIGN(CJ4-CK4)=SIGN($CL$2-$CM$2),OR(CJ4=$CL$2,CK4=$CM$2)),4,IF(SIGN(CJ4-CK4)=SIGN($CL$2-$CM$2),3,IF(OR(CJ4=$CL$2,CK4=$CM$2),1,0))))) -> 0 | CN4: 1 | CO4: 1 | CP4: =IF(AND(CN4="",CO4=""),0,IF(AND(CN4=$CP$2,CO4=$CQ$2),5,IF(AND(SIGN(CN4-CO4)=SIGN($CP$2-$CQ$2),OR(CN4=$CP$2,CO4=$CQ$2)),4,IF(SIGN(CN4-CO4)=SIGN($CP$2-$CQ$2),3,IF(OR(CN4=$CP$2,CO4=$CQ$2),1,0))))) -> 0 | CR4: 2 | CS4: 0 | CT4: =IF(AND(CR4="",CS4=""),0,IF(AND(CR4=$CT$2,CS4=$CU$2),5,IF(AND(SIGN(CR4-CS4)=SIGN($CT$2-$CU$2),OR(CR4=$CT$2,CS4=$CU$2)),4,IF(SIGN(CR4-CS4)=SIGN($CT$2-$CU$2),3,IF(OR(CR4=$CT$2,CS4=$CU$2),1,0))))) -> 4 | CV4: 0 | CW4: 2 | CX4: =IF(AND(CV4="",CW4=""),0,IF(AND(CV4=$CX$2,CW4=$CY$2),5,IF(AND(SIGN(CV4-CW4)=SIGN($CX$2-$CY$2),OR(CV4=$CX$2,CW4=$CY$2)),4,IF(SIGN(CV4-CW4)=SIGN($CX$2-$CY$2),3,IF(OR(CV4=$CX$2,CW4=$CY$2),1,0))))) -> 3 | CZ4: =CL4+CP4+CT4+CX4 -> 7 | DA4: 2 | DB4: 0 | DC4: =IF(AND(DA4="",DB4=""),0,IF(AND(DA4=$DC$2,DB4=$DD$2),5,IF(AND(SIGN(DA4-DB4)=SIGN($DC$2-$DD$2),OR(DA4=$DC$2,DB4=$DD$2)),4,IF(SIGN(DA4-DB4)=SIGN($DC$2-$DD$2),3,IF(OR(DA4=$DC$2,DB4=$DD$2),1,0))))) -> 0 | DE4: 1 | DF4: 1 | DG4: =IF(AND(DE4="",DF4=""),0,IF(AND(DE4=$DG$2,DF4=$DH$2),5,IF(AND(SIGN(DE4-DF4)=SIGN($DG$2-$DH$2),OR(DE4=$DG$2,DF4=$DH$2)),4,IF(SIGN(DE4-DF4)=SIGN($DG$2-$DH$2),3,IF(OR(DE4=$DG$2,DF4=$DH$2),1,0))))) -> 1 | DI4: 2 | DJ4: 0 | DK4: =IF(AND(DI4="",DJ4=""),0,IF(AND(DI4=$DK$2,DJ4=$DL$2),5,IF(AND(SIGN(DI4-DJ4)=SIGN($DK$2-$DL$2),OR(DI4=$DK$2,DJ4=$DL$2)),4,IF(SIGN(DI4-DJ4)=SIGN($DK$2-$DL$2),3,IF(OR(DI4=$DK$2,DJ4=$DL$2),1,0))))) -> 4 | DM4: 1 | DN4: 1 | DO4: =IF(AND(DM4="",DN4=""),0,IF(AND(DM4=$DO$2,DN4=$DP$2),5,IF(AND(SIGN(DM4-DN4)=SIGN($DO$2-$DP$2),OR(DM4=$DO$2,DN4=$DP$2)),4,IF(SIGN(DM4-DN4)=SIGN($DO$2-$DP$2),3,IF(OR(DM4=$DO$2,DN4=$DP$2),1,0))))) -> 1 | DQ4: =DC4+DG4+DK4+DO4 -> 6 | DR4: 3 | DS4: 1 | DT4: =IF(AND(DR4="",DS4=""),0,IF(AND(DR4=$DT$2,DS4=$DU$2),5,IF(AND(SIGN(DR4-DS4)=SIGN($DT$2-$DU$2),OR(DR4=$DT$2,DS4=$DU$2)),4,IF(SIGN(DR4-DS4)=SIGN($DT$2-$DU$2),3,IF(OR(DR4=$DT$2,DS4=$DU$2),1,0))))) -> 3 | DV4: 0 | DW4: 2 | DX4: =IF(AND(DV4="",DW4=""),0,IF(AND(DV4=$DX$2,DW4=$DY$2),5,IF(AND(SIGN(DV4-DW4)=SIGN($DX$2-$DY$2),OR(DV4=$DX$2,DW4=$DY$2)),4,IF(SIGN(DV4-DW4)=SIGN($DX$2-$DY$2),3,IF(OR(DV4=$DX$2,DW4=$DY$2),1,0))))) -> 4 | DZ4: 3 | EA4: 0 | EB4: =IF(AND(DZ4="",EA4=""),0,IF(AND(DZ4=$EB$2,EA4=$EC$2),5,IF(AND(SIGN(DZ4-EA4)=SIGN($EB$2-$EC$2),OR(DZ4=$EB$2,EA4=$EC$2)),4,IF(SIGN(DZ4-EA4)=SIGN($EB$2-$EC$2),3,IF(OR(DZ4=$EB$2,EA4=$EC$2),1,0))))) -> 5 | ED4: 1 | EE4: 2 | EF4: =IF(AND(ED4="",EE4=""),0,IF(AND(ED4=$EF$2,EE4=$EG$2),5,IF(AND(SIGN(ED4-EE4)=SIGN($EF$2-$EG$2),OR(ED4=$EF$2,EE4=$EG$2)),4,IF(SIGN(ED4-EE4)=SIGN($EF$2-$EG$2),3,IF(OR(ED4=$EF$2,EE4=$EG$2),1,0))))) -> 3 | EH4: =DT4+DX4+EB4+EF4 -> 15 | EI4: 3 | EJ4: 1 | EK4: =IF(AND(EI4="",EJ4=""),0,IF(AND(EI4=$EK$2,EJ4=$EL$2),5,IF(AND(SIGN(EI4-EJ4)=SIGN($EK$2-$EL$2),OR(EI4=$EK$2,EJ4=$EL$2)),4,IF(SIGN(EI4-EJ4)=SIGN($EK$2-$EL$2),3,IF(OR(EI4=$EK$2,EJ4=$EL$2),1,0))))) -> 4 | EM4: 4 | EN4: 1 | EO4: =IF(AND(EM4="",EN4=""),0,IF(AND(EM4=$EO$2,EN4=$EP$2),5,IF(AND(SIGN(EM4-EN4)=SIGN($EO$2-$EP$2),OR(EM4=$EO$2,EN4=$EP$2)),4,IF(SIGN(EM4-EN4)=SIGN($EO$2-$EP$2),3,IF(OR(EM4=$EO$2,EN4=$EP$2),1,0))))) -> 4 | EQ4: 3 | ER4: 0 | ES4: =IF(AND(EQ4="",ER4=""),0,IF(AND(EQ4=$ES$2,ER4=$ET$2),5,IF(AND(SIGN(EQ4-ER4)=SIGN($ES$2-$ET$2),OR(EQ4=$ES$2,ER4=$ET$2)),4,IF(SIGN(EQ4-ER4)=SIGN($ES$2-$ET$2),3,IF(OR(EQ4=$ES$2,ER4=$ET$2),1,0))))) -> 1 | EU4: 0 | EV4: 2 | EW4: =IF(AND(EU4="",EV4=""),0,IF(AND(EU4=$EW$2,EV4=$EX$2),5,IF(AND(SIGN(EU4-EV4)=SIGN($EW$2-$EX$2),OR(EU4=$EW$2,EV4=$EX$2)),4,IF(SIGN(EU4-EV4)=SIGN($EW$2-$EX$2),3,IF(OR(EU4=$EW$2,EV4=$EX$2),1,0))))) -> 4 | EY4: =EK4+EO4+ES4+EW4 -> 13 | EZ4: 3 | FA4: 0 | FD4: 3 | FE4: 0 | FH4: 2 | FI4: 0 | FL4: 0 | FM4: 2 | FP4: =FB4+FF4+FJ4+FN4 -> 0 | FS4: =IF(AND(FQ4="",FR4=""),0,IF(AND(FQ4=$FS$2,FR4=$FT$2),5,IF(AND(SIGN(FQ4-FR4)=SIGN($FS$2-$FT$2),OR(FQ4=$FS$2,FR4=$FT$2)),4,IF(SIGN(FQ4-FR4)=SIGN($FS$2-$FT$2),3,IF(OR(FQ4=$FS$2,FR4=$FT$2),1,0))))) -> 0 | FW4: =IF(AND(FU4="",FV4=""),0,IF(AND(FU4=$FW$2,FV4=$FX$2),5,IF(AND(SIGN(FU4-FV4)=SIGN($FW$2-$FX$2),OR(FU4=$FW$2,FV4=$FX$2)),4,IF(SIGN(FU4-FV4)=SIGN($FW$2-$FX$2),3,IF(OR(FU4=$FW$2,FV4=$FX$2),1,0))))) -> 0 | GA4: =IF(AND(FY4="",FZ4=""),0,IF(AND(FY4=$GA$2,FZ4=$GB$2),5,IF(AND(SIGN(FY4-FZ4)=SIGN($GA$2-$GB$2),OR(FY4=$GA$2,FZ4=$GB$2)),4,IF(SIGN(FY4-FZ4)=SIGN($GA$2-$GB$2),3,IF(OR(FY4=$GA$2,FZ4=$GB$2),1,0))))) -> 0 | GE4: =IF(AND(GC4="",GD4=""),0,IF(AND(GC4=$GE$2,GD4=$GF$2),5,IF(AND(SIGN(GC4-GD4)=SIGN($GE$2-$GF$2),OR(GC4=$GE$2,GD4=$GF$2)),4,IF(SIGN(GC4-GD4)=SIGN($GE$2-$GF$2),3,IF(OR(GC4=$GE$2,GD4=$GF$2),1,0))))) -> 0 | GG4: =FS4+FW4+GA4+GE4 -> 0 | GJ4: =IF(AND(GH4="",GI4=""),0,IF(AND(GH4=$GJ$2,GI4=$GK$2),5,IF(AND(SIGN(GH4-GI4)=SIGN($GJ$2-$GK$2),OR(GH4=$GJ$2,GI4=$GK$2)),4,IF(SIGN(GH4-GI4)=SIGN($GJ$2-$GK$2),3,IF(OR(GH4=$GJ$2,GI4=$GK$2),1,0))))) -> 0 | GN4: =IF(AND(GL4="",GM4=""),0,IF(AND(GL4=$GN$2,GM4=$GO$2),5,IF(AND(SIGN(GL4-GM4)=SIGN($GN$2-$GO$2),OR(GL4=$GN$2,GM4=$GO$2)),4,IF(SIGN(GL4-GM4)=SIGN($GN$2-$GO$2),3,IF(OR(GL4=$GN$2,GM4=$GO$2),1,0))))) -> 0 | GR4: =IF(AND(GP4="",GQ4=""),0,IF(AND(GP4=$GR$2,GQ4=$GS$2),5,IF(AND(SIGN(GP4-GQ4)=SIGN($GR$2-$GS$2),OR(GP4=$GR$2,GQ4=$GS$2)),4,IF(SIGN(GP4-GQ4)=SIGN($GR$2-$GS$2),3,IF(OR(GP4=$GR$2,GQ4=$GS$2),1,0))))) -> 0 | GV4: =IF(AND(GT4="",GU4=""),0,IF(AND(GT4=$GV$2,GU4=$GW$2),5,IF(AND(SIGN(GT4-GU4)=SIGN($GV$2-$GW$2),OR(GT4=$GV$2,GU4=$GW$2)),4,IF(SIGN(GT4-GU4)=SIGN($GV$2-$GW$2),3,IF(OR(GT4=$GV$2,GU4=$GW$2),1,0))))) -> 0 | GX4: =GJ4+GN4+GR4+GV4 -> 0 | HA4: =IF(AND(GY4="",GZ4=""),0,IF(AND(GY4=$HA$2,GZ4=$HB$2),5,IF(AND(SIGN(GY4-GZ4)=SIGN($HA$2-$HB$2),OR(GY4=$HA$2,GZ4=$HB$2)),4,IF(SIGN(GY4-GZ4)=SIGN($HA$2-$HB$2),3,IF(OR(GY4=$HA$2,GZ4=$HB$2),1,0))))) -> 0 | HE4: =IF(AND(HC4="",HD4=""),0,IF(AND(HC4=$HE$2,HD4=$HF$2),5,IF(AND(SIGN(HC4-HD4)=SIGN($HE$2-$HF$2),OR(HC4=$HE$2,HD4=$HF$2)),4,IF(SIGN(HC4-HD4)=SIGN($HE$2-$HF$2),3,IF(OR(HC4=$HE$2,HD4=$HF$2),1,0))))) -> 0 | HI4: =IF(AND(HG4="",HH4=""),0,IF(AND(HG4=$HI$2,HH4=$HJ$2),5,IF(AND(SIGN(HG4-HH4)=SIGN($HI$2-$HJ$2),OR(HG4=$HI$2,HH4=$HJ$2)),4,IF(SIGN(HG4-HH4)=SIGN($HI$2-$HJ$2),3,IF(OR(HG4=$HI$2,HH4=$HJ$2),1,0))))) -> 0 | HM4: =IF(AND(HK4="",HL4=""),0,IF(AND(HK4=$HM$2,HL4=$HN$2),5,IF(AND(SIGN(HK4-HL4)=SIGN($HM$2-$HN$2),OR(HK4=$HM$2,HL4=$HN$2)),4,IF(SIGN(HK4-HL4)=SIGN($HM$2-$HN$2),3,IF(OR(HK4=$HM$2,HL4=$HN$2),1,0))))) -> 0 | HQ4: =IF(AND(HO4="",HP4=""),0,IF(AND(HO4=$HQ$2,HP4=$HR$2),5,IF(AND(SIGN(HO4-HP4)=SIGN($HQ$2-$HR$2),OR(HO4=$HQ$2,HP4=$HR$2)),4,IF(SIGN(HO4-HP4)=SIGN($HQ$2-$HR$2),3,IF(OR(HO4=$HQ$2,HP4=$HR$2),1,0))))) -> 0 | HU4: =IF(AND(HS4="",HT4=""),0,IF(AND(HS4=$HU$2,HT4=$HV$2),5,IF(AND(SIGN(HS4-HT4)=SIGN($HU$2-$HV$2),OR(HS4=$HU$2,HT4=$HV$2)),4,IF(SIGN(HS4-HT4)=SIGN($HU$2-$HV$2),3,IF(OR(HS4=$HU$2,HT4=$HV$2),1,0))))) -> 0 | HW4: =HI4+HM4+HQ4+HU4+HE4+HA4 -> 0 | HZ4: =IF(AND(HX4="",HY4=""),0,IF(AND(HX4=$HZ$2,HY4=$IA$2),5,IF(AND(SIGN(HX4-HY4)=SIGN($HZ$2-$IA$2),OR(HX4=$HZ$2,HY4=$IA$2)),4,IF(SIGN(HX4-HY4)=SIGN($HZ$2-$IA$2),3,IF(OR(HX4=$HZ$2,HY4=$IA$2),1,0))))) -> 0 | ID4: =IF(AND(IB4="",IC4=""),0,IF(AND(IB4=$ID$2,IC4=$IE$2),5,IF(AND(SIGN(IB4-IC4)=SIGN($ID$2-$IE$2),OR(IB4=$ID$2,IC4=$IE$2)),4,IF(SIGN(IB4-IC4)=SIGN($ID$2-$IE$2),3,IF(OR(IB4=$ID$2,IC4=$IE$2),1,0))))) -> 0 | IH4: =IF(AND(IF4="",IG4=""),0,IF(AND(IF4=$IH$2,IG4=$II$2),5,IF(AND(SIGN(IF4-IG4)=SIGN($IH$2-$II$2),OR(IF4=$IH$2,IG4=$II$2)),4,IF(SIGN(IF4-IG4)=SIGN($IH$2-$II$2),3,IF(OR(IF4=$IH$2,IG4=$II$2),1,0))))) -> 0 | IL4: =IF(AND(IJ4="",IK4=""),0,IF(AND(IJ4=$IL$2,IK4=$IM$2),5,IF(AND(SIGN(IJ4-IK4)=SIGN($IL$2-$IM$2),OR(IJ4=$IL$2,IK4=$IM$2)),4,IF(SIGN(IJ4-IK4)=SIGN($IL$2-$IM$2),3,IF(OR(IJ4=$IL$2,IK4=$IM$2),1,0))))) -> 0 | IP4: =IF(AND(IN4="",IO4=""),0,IF(AND(IN4=$IP$2,IO4=$IQ$2),5,IF(AND(SIGN(IN4-IO4)=SIGN($IP$2-$IQ$2),OR(IN4=$IP$2,IO4=$IQ$2)),4,IF(SIGN(IN4-IO4)=SIGN($IP$2-$IQ$2),3,IF(OR(IN4=$IP$2,IO4=$IQ$2),1,0))))) -> 0 | IT4: =IF(AND(IR4="",IS4=""),0,IF(AND(IR4=$IT$2,IS4=$IU$2),5,IF(AND(SIGN(IR4-IS4)=SIGN($IT$2-$IU$2),OR(IR4=$IT$2,IS4=$IU$2)),4,IF(SIGN(IR4-IS4)=SIGN($IT$2-$IU$2),3,IF(OR(IR4=$IT$2,IS4=$IU$2),1,0))))) -> 0 | IV4: =IH4+IL4+IP4+IT4+ID4+HZ4 -> 0 | IY4: =IF(AND(IW4="",IX4=""),0,IF(AND(IW4=$IY$2,IX4=$IZ$2),5,IF(AND(SIGN(IW4-IX4)=SIGN($IY$2-$IZ$2),OR(IW4=$IY$2,IX4=$IZ$2)),4,IF(SIGN(IW4-IX4)=SIGN($IY$2-$IZ$2),3,IF(OR(IW4=$IY$2,IX4=$IZ$2),1,0))))) -> 0 | JC4: =IF(AND(JA4="",JB4=""),0,IF(AND(JA4=$JC$2,JB4=$JD$2),5,IF(AND(SIGN(JA4-JB4)=SIGN($JC$2-$JD$2),OR(JA4=$JC$2,JB4=$JD$2)),4,IF(SIGN(JA4-JB4)=SIGN($JC$2-$JD$2),3,IF(OR(JA4=$JC$2,JB4=$JD$2),1,0))))) -> 0 | JG4: =IF(AND(JE4="",JF4=""),0,IF(AND(JE4=$JG$2,JF4=$JH$2),5,IF(AND(SIGN(JE4-JF4)=SIGN($JG$2-$JH$2),OR(JE4=$JG$2,JF4=$JH$2)),4,IF(SIGN(JE4-JF4)=SIGN($JG$2-$JH$2),3,IF(OR(JE4=$JG$2,JF4=$JH$2),1,0))))) -> 0 | JK4: =IF(AND(JI4="",JJ4=""),0,IF(AND(JI4=$JK$2,JJ4=$JL$2),5,IF(AND(SIGN(JI4-JJ4)=SIGN($JK$2-$JL$2),OR(JI4=$JK$2,JJ4=$JL$2)),4,IF(SIGN(JI4-JJ4)=SIGN($JK$2-$JL$2),3,IF(OR(JI4=$JK$2,JJ4=$JL$2),1,0))))) -> 0 | JO4: =IF(AND(JM4="",JN4=""),0,IF(AND(JM4=$JO$2,JN4=$JP$2),5,IF(AND(SIGN(JM4-JN4)=SIGN($JO$2-$JP$2),OR(JM4=$JO$2,JN4=$JP$2)),4,IF(SIGN(JM4-JN4)=SIGN($JO$2-$JP$2),3,IF(OR(JM4=$JO$2,JN4=$JP$2),1,0))))) -> 0 | JS4: =IF(AND(JQ4="",JR4=""),0,IF(AND(JQ4=$JS$2,JR4=$JT$2),5,IF(AND(SIGN(JQ4-JR4)=SIGN($JS$2-$JT$2),OR(JQ4=$JS$2,JR4=$JT$2)),4,IF(SIGN(JQ4-JR4)=SIGN($JS$2-$JT$2),3,IF(OR(JQ4=$JS$2,JR4=$JT$2),1,0))))) -> 0 | JU4: =JG4+JK4+JO4+JS4+JC4+IY4 -> 0 | JX4: =IF(AND(JV4="",JW4=""),0,IF(AND(JV4=$JX$2,JW4=$JY$2),5,IF(AND(SIGN(JV4-JW4)=SIGN($JX$2-$JY$2),OR(JV4=$JX$2,JW4=$JY$2)),4,IF(SIGN(JV4-JW4)=SIGN($JX$2-$JY$2),3,IF(OR(JV4=$JX$2,JW4=$JY$2),1,0))))) -> 0 | KB4: =IF(AND(JZ4="",KA4=""),0,IF(AND(JZ4=$KB$2,KA4=$KC$2),5,IF(AND(SIGN(JZ4-KA4)=SIGN($KB$2-$KC$2),OR(JZ4=$KB$2,KA4=$KC$2)),4,IF(SIGN(JZ4-KA4)=SIGN($KB$2-$KC$2),3,IF(OR(JZ4=$KB$2,KA4=$KC$2),1,0))))) -> 0 | KF4: =IF(AND(KD4="",KE4=""),0,IF(AND(KD4=$KF$2,KE4=$KG$2),5,IF(AND(SIGN(KD4-KE4)=SIGN($KF$2-$KG$2),OR(KD4=$KF$2,KE4=$KG$2)),4,IF(SIGN(KD4-KE4)=SIGN($KF$2-$KG$2),3,IF(OR(KD4=$KF$2,KE4=$KG$2),1,0))))) -> 0 | KJ4: =IF(AND(KH4="",KI4=""),0,IF(AND(KH4=$KJ$2,KI4=$KK$2),5,IF(AND(SIGN(KH4-KI4)=SIGN($KJ$2-$KK$2),OR(KH4=$KJ$2,KI4=$KK$2)),4,IF(SIGN(KH4-KI4)=SIGN($KJ$2-$KK$2),3,IF(OR(KH4=$KJ$2,KI4=$KK$2),1,0))))) -> 0 | KN4: =IF(AND(KL4="",KM4=""),0,IF(AND(KL4=$KN$2,KM4=$KO$2),5,IF(AND(SIGN(KL4-KM4)=SIGN($KN$2-$KO$2),OR(KL4=$KN$2,KM4=$KO$2)),4,IF(SIGN(KL4-KM4)=SIGN($KN$2-$KO$2),3,IF(OR(KL4=$KN$2,KM4=$KO$2),1,0))))) -> 0 | KR4: =IF(AND(KP4="",KQ4=""),0,IF(AND(KP4=$KR$2,KQ4=$KS$2),5,IF(AND(SIGN(KP4-KQ4)=SIGN($KR$2-$KS$2),OR(KP4=$KR$2,KQ4=$KS$2)),4,IF(SIGN(KP4-KQ4)=SIGN($KR$2-$KS$2),3,IF(OR(KP4=$KR$2,KQ4=$KS$2),1,0))))) -> 0 | KT4: =KF4+KJ4+KN4+KR4+KB4+JX4 -> 0 | KW4: =IF(AND(KU4="",KV4=""),0,IF(AND(KU4=$KW$2,KV4=$KX$2),5,IF(AND(SIGN(KU4-KV4)=SIGN($KW$2-$KX$2),OR(KU4=$KW$2,KV4=$KX$2)),4,IF(SIGN(KU4-KV4)=SIGN($KW$2-$KX$2),3,IF(OR(KU4=$KW$2,KV4=$KX$2),1,0))))) -> 0 | KY4: =KW4 -> 0 | LB4: =IF(AND(KZ4="",LA4=""),0,IF(AND(KZ4=$LB$2,LA4=$LC$2),5,IF(AND(SIGN(KZ4-LA4)=SIGN($LB$2-$LC$2),OR(KZ4=$LB$2,LA4=$LC$2)),4,IF(SIGN(KZ4-LA4)=SIGN($LB$2-$LC$2),3,IF(OR(KZ4=$LB$2,LA4=$LC$2),1,0))))) -> 0 | LF4: =IF(AND(LD4="",LE4=""),0,IF(AND(LD4=$LF$2,LE4=$LG$2),5,IF(AND(SIGN(LD4-LE4)=SIGN($LF$2-$LG$2),OR(LD4=$LF$2,LE4=$LG$2)),4,IF(SIGN(LD4-LE4)=SIGN($LF$2-$LG$2),3,IF(OR(LD4=$LF$2,LE4=$LG$2),1,0))))) -> 0 | LJ4: =IF(AND(LH4="",LI4=""),0,IF(AND(LH4=$LJ$2,LI4=$LK$2),5,IF(AND(SIGN(LH4-LI4)=SIGN($LJ$2-$LK$2),OR(LH4=$LJ$2,LI4=$LK$2)),4,IF(SIGN(LH4-LI4)=SIGN($LJ$2-$LK$2),3,IF(OR(LH4=$LJ$2,LI4=$LK$2),1,0))))) -> 0 | LL4: =LB4+LF4+LJ4 -> 0 | LO4: =IF(AND(LM4="",LN4=""),0,IF(AND(LM4=$LO$2,LN4=$LP$2),5,IF(AND(SIGN(LM4-LN4)=SIGN($LO$2-$LP$2),OR(LM4=$LO$2,LN4=$LP$2)),4,IF(SIGN(LM4-LN4)=SIGN($LO$2-$LP$2),3,IF(OR(LM4=$LO$2,LN4=$LP$2),1,0))))) -> 0 | LS4: =IF(AND(LQ4="",LR4=""),0,IF(AND(LQ4=$LS$2,LR4=$LT$2),5,IF(AND(SIGN(LQ4-LR4)=SIGN($LS$2-$LT$2),OR(LQ4=$LS$2,LR4=$LT$2)),4,IF(SIGN(LQ4-LR4)=SIGN($LS$2-$LT$2),3,IF(OR(LQ4=$LS$2,LR4=$LT$2),1,0))))) -> 0 | LW4: =IF(AND(LU4="",LV4=""),0,IF(AND(LU4=$LW$2,LV4=$LX$2),5,IF(AND(SIGN(LU4-LV4)=SIGN($LW$2-$LX$2),OR(LU4=$LW$2,LV4=$LX$2)),4,IF(SIGN(LU4-LV4)=SIGN($LW$2-$LX$2),3,IF(OR(LU4=$LW$2,LV4=$LX$2),1,0))))) -> 0 | LY4: =LO4+LS4+LW4 -> 0 | MB4: =IF(AND(LZ4="",MA4=""),0,IF(AND(LZ4=$MB$2,MA4=$MC$2),5,IF(AND(SIGN(LZ4-MA4)=SIGN($MB$2-$MC$2),OR(LZ4=$MB$2,MA4=$MC$2)),4,IF(SIGN(LZ4-MA4)=SIGN($MB$2-$MC$2),3,IF(OR(LZ4=$MB$2,MA4=$MC$2),1,0))))) -> 0 | MF4: =IF(AND(MD4="",ME4=""),0,IF(AND(MD4=$MF$2,ME4=$MG$2),5,IF(AND(SIGN(MD4-ME4)=SIGN($MF$2-$MG$2),OR(MD4=$MF$2,ME4=$MG$2)),4,IF(SIGN(MD4-ME4)=SIGN($MF$2-$MG$2),3,IF(OR(MD4=$MF$2,ME4=$MG$2),1,0))))) -> 0 | MJ4: =IF(AND(MH4="",MI4=""),0,IF(AND(MH4=$MJ$2,MI4=$MK$2),5,IF(AND(SIGN(MH4-MI4)=SIGN($MJ$2-$MK$2),OR(MH4=$MJ$2,MI4=$MK$2)),4,IF(SIGN(MH4-MI4)=SIGN($MJ$2-$MK$2),3,IF(OR(MH4=$MJ$2,MI4=$MK$2),1,0))))) -> 0 | ML4: =MB4+MF4+MJ4 -> 0 | MO4: =IF(AND(MM4="",MN4=""),0,IF(AND(MM4=$MO$2,MN4=$MP$2),5,IF(AND(SIGN(MM4-MN4)=SIGN($MO$2-$MP$2),OR(MM4=$MO$2,MN4=$MP$2)),4,IF(SIGN(MM4-MN4)=SIGN($MO$2-$MP$2),3,IF(OR(MM4=$MO$2,MN4=$MP$2),1,0))))) -> 0 | MS4: =IF(AND(MQ4="",MR4=""),0,IF(AND(MQ4=$MS$2,MR4=$MT$2),5,IF(AND(SIGN(MQ4-MR4)=SIGN($MS$2-$MT$2),OR(MQ4=$MS$2,MR4=$MT$2)),4,IF(SIGN(MQ4-MR4)=SIGN($MS$2-$MT$2),3,IF(OR(MQ4=$MS$2,MR4=$MT$2),1,0))))) -> 0 | MW4: =IF(AND(MU4="",MV4=""),0,IF(AND(MU4=$MW$2,MV4=$MX$2),5,IF(AND(SIGN(MU4-MV4)=SIGN($MW$2-$MX$2),OR(MU4=$MW$2,MV4=$MX$2)),4,IF(SIGN(MU4-MV4)=SIGN($MW$2-$MX$2),3,IF(OR(MU4=$MW$2,MV4=$MX$2),1,0))))) -> 0 | MY4: =MO4+MS4+MW4 -> 0 | NB4: =IF(AND(MZ4="",NA4=""),0,IF(AND(MZ4=$NB$2,NA4=$NC$2),5,IF(AND(SIGN(MZ4-NA4)=SIGN($NB$2-$NC$2),OR(MZ4=$NB$2,NA4=$NC$2)),4,IF(SIGN(MZ4-NA4)=SIGN($NB$2-$NC$2),3,IF(OR(MZ4=$NB$2,NA4=$NC$2),1,0))))) -> 0 | NF4: =IF(AND(ND4="",NE4=""),0,IF(AND(ND4=$NF$2,NE4=$NG$2),5,IF(AND(SIGN(ND4-NE4)=SIGN($NF$2-$NG$2),OR(ND4=$NF$2,NE4=$NG$2)),4,IF(SIGN(ND4-NE4)=SIGN($NF$2-$NG$2),3,IF(OR(ND4=$NF$2,NE4=$NG$2),1,0))))) -> 0 | NJ4: =IF(AND(NH4="",NI4=""),0,IF(AND(NH4=$NJ$2,NI4=$NK$2),5,IF(AND(SIGN(NH4-NI4)=SIGN($NJ$2-$NK$2),OR(NH4=$NJ$2,NI4=$NK$2)),4,IF(SIGN(NH4-NI4)=SIGN($NJ$2-$NK$2),3,IF(OR(NH4=$NJ$2,NI4=$NK$2),1,0))))) -> 0 | NL4: =NB4+NF4+NJ4 -> 0 | NO4: =IF(AND(NM4="",NN4=""),0,IF(AND(NM4=$NO$2,NN4=$NP$2),5,IF(AND(SIGN(NM4-NN4)=SIGN($NO$2-$NP$2),OR(NM4=$NO$2,NN4=$NP$2)),4,IF(SIGN(NM4-NN4)=SIGN($NO$2-$NP$2),3,IF(OR(NM4=$NO$2,NN4=$NP$2),1,0))))) -> 0 | NS4: =IF(AND(NQ4="",NR4=""),0,IF(AND(NQ4=$NS$2,NR4=$NT$2),5,IF(AND(SIGN(NQ4-NR4)=SIGN($NS$2-$NT$2),OR(NQ4=$NS$2,NR4=$NT$2)),4,IF(SIGN(NQ4-NR4)=SIGN($NS$2-$NT$2),3,IF(OR(NQ4=$NS$2,NR4=$NT$2),1,0))))) -> 0 | NU4: =NO4+NS4 -> 0 | NX4: =IF(AND(NV4="",NW4=""),0,IF(AND(NV4=$NX$2,NW4=$NY$2),5,IF(AND(SIGN(NV4-NW4)=SIGN($NX$2-$NY$2),OR(NV4=$NX$2,NW4=$NY$2)),4,IF(SIGN(NV4-NW4)=SIGN($NX$2-$NY$2),3,IF(OR(NV4=$NX$2,NW4=$NY$2),1,0))))) -> 0 | OB4: =IF(AND(NZ4="",OA4=""),0,IF(AND(NZ4=$OB$2,OA4=$OC$2),5,IF(AND(SIGN(NZ4-OA4)=SIGN($OB$2-$OC$2),OR(NZ4=$OB$2,OA4=$OC$2)),4,IF(SIGN(NZ4-OA4)=SIGN($OB$2-$OC$2),3,IF(OR(NZ4=$OB$2,OA4=$OC$2),1,0))))) -> 0 | OD4: =NX4+OB4 -> 0 | OG4: =IF(AND(OE4="",OF4=""),0,IF(AND(OE4=$OG$2,OF4=$OH$2),5,IF(AND(SIGN(OE4-OF4)=SIGN($OG$2-$OH$2),OR(OE4=$OG$2,OF4=$OH$2)),4,IF(SIGN(OE4-OF4)=SIGN($OG$2-$OH$2),3,IF(OR(OE4=$OG$2,OF4=$OH$2),1,0))))) -> 0 | OK4: =IF(AND(OI4="",OJ4=""),0,IF(AND(OI4=$OK$2,OJ4=$OL$2),5,IF(AND(SIGN(OI4-OJ4)=SIGN($OK$2-$OL$2),OR(OI4=$OK$2,OJ4=$OL$2)),4,IF(SIGN(OI4-OJ4)=SIGN($OK$2-$OL$2),3,IF(OR(OI4=$OK$2,OJ4=$OL$2),1,0))))) -> 0 | OM4: =OG4+OK4 -> 0 | OP4: =IF(AND(ON4="",OO4=""),0,IF(AND(ON4=$OP$2,OO4=$OQ$2),5,IF(AND(SIGN(ON4-OO4)=SIGN($OP$2-$OQ$2),OR(ON4=$OP$2,OO4=$OQ$2)),4,IF(SIGN(ON4-OO4)=SIGN($OP$2-$OQ$2),3,IF(OR(ON4=$OP$2,OO4=$OQ$2),1,0))))) -> 0 | OT4: =IF(AND(OR4="",OS4=""),0,IF(AND(OR4=$OT$2,OS4=$OU$2),5,IF(AND(SIGN(OR4-OS4)=SIGN($OT$2-$OU$2),OR(OR4=$OT$2,OS4=$OU$2)),4,IF(SIGN(OR4-OS4)=SIGN($OT$2-$OU$2),3,IF(OR(OR4=$OT$2,OS4=$OU$2),1,0))))) -> 0 | OV4: =OP4+OT4 -> 0 | OY4: =IF(AND(OW4="",OX4=""),0,IF(AND(OW4=$OY$2,OX4=$OZ$2),5,IF(AND(SIGN(OW4-OX4)=SIGN($OY$2-$OZ$2),OR(OW4=$OY$2,OX4=$OZ$2)),4,IF(SIGN(OW4-OX4)=SIGN($OY$2-$OZ$2),3,IF(OR(OW4=$OY$2,OX4=$OZ$2),1,0))))) -> 0 | PA4: =OY4 -> 0 | PD4: =IF(AND(PB4="",PC4=""),0,IF(AND(PB4=$PD$2,PC4=$PE$2),5,IF(AND(SIGN(PB4-PC4)=SIGN($PD$2-$PE$2),OR(PB4=$PD$2,PC4=$PE$2)),4,IF(SIGN(PB4-PC4)=SIGN($PD$2-$PE$2),3,IF(OR(PB4=$PD$2,PC4=$PE$2),1,0))))) -> 0 | PF4: =PD4 -> 0 | PI4: =IF(AND(PG4="",PH4=""),0,IF(AND(PG4=$PI$2,PH4=$PJ$2),5,IF(AND(SIGN(PG4-PH4)=SIGN($PI$2-$PJ$2),OR(PG4=$PI$2,PH4=$PJ$2)),4,IF(SIGN(PG4-PH4)=SIGN($PI$2-$PJ$2),3,IF(OR(PG4=$PI$2,PH4=$PJ$2),1,0))))) -> 0 | PM4: =IF(AND(PK4="",PL4=""),0,IF(AND(PK4=$PM$2,PL4=$PN$2),5,IF(AND(SIGN(PK4-PL4)=SIGN($PM$2-$PN$2),OR(PK4=$PM$2,PL4=$PN$2)),4,IF(SIGN(PK4-PL4)=SIGN($PM$2-$PN$2),3,IF(OR(PK4=$PM$2,PL4=$PN$2),1,0))))) -> 0 | PO4: =PI4+PM4 -> 0 | PR4: =IF(AND(PP4="",PQ4=""),0,IF(AND(PP4=$PR$2,PQ4=$PS$2),5,IF(AND(SIGN(PP4-PQ4)=SIGN($PR$2-$PS$2),OR(PP4=$PR$2,PQ4=$PS$2)),4,IF(SIGN(PP4-PQ4)=SIGN($PR$2-$PS$2),3,IF(OR(PP4=$PR$2,PQ4=$PS$2),1,0))))) -> 0 | PT4: =PR4 -> 0 | PW4: =IF(AND(PU4="",PV4=""),0,IF(AND(PU4=$PW$2,PV4=$PX$2),5,IF(AND(SIGN(PU4-PV4)=SIGN($PW$2-$PX$2),OR(PU4=$PW$2,PV4=$PX$2)),4,IF(SIGN(PU4-PV4)=SIGN($PW$2-$PX$2),3,IF(OR(PU4=$PW$2,PV4=$PX$2),1,0))))) -> 0 | PY4: =PW4 -> 0 | QB4: =IF(AND(PZ4="",QA4=""),0,IF(AND(PZ4=$QB$2,QA4=$QC$2),5,IF(AND(SIGN(PZ4-QA4)=SIGN($QB$2-$QC$2),OR(PZ4=$QB$2,QA4=$QC$2)),4,IF(SIGN(PZ4-QA4)=SIGN($QB$2-$QC$2),3,IF(OR(PZ4=$QB$2,QA4=$QC$2),1,0))))) -> 0 | QD4: =QB4 -> 0 | QG4: =IF(AND(QE4="",QF4=""),0,IF(AND(QE4=$QG$2,QF4=$QH$2),5,IF(AND(SIGN(QE4-QF4)=SIGN($QG$2-$QH$2),OR(QE4=$QG$2,QF4=$QH$2)),4,IF(SIGN(QE4-QF4)=SIGN($QG$2-$QH$2),3,IF(OR(QE4=$QG$2,QF4=$QH$2),1,0))))) -> 0 | QI4: =QG4 -> 0
A5: Sergio Echeverria | B5: 3 | C5: 1 | D5: =IF( AND(B5=$D$2, C5=$E$2), 5, IF( AND( SIGN(B5-C5)=SIGN($D$2-$E$2), OR(B5=$D$2, C5=$E$2) ), 4, IF( SIGN(B5-C5)=SIGN($D$2-$E$2), 3, IF( OR(B5=$D$2, C5=$E$2), 1, 0 ) ) )) -> 3 | F5: 3 | G5: 1 | H5: =IF( AND(F5=$H$2, G5=$I$2), 5, IF( AND( SIGN(F5-G5)=SIGN($H$2-$I$2), OR(F5=$H$2, G5=$I$2) ), 4, IF( SIGN(F5-G5)=SIGN($H$2-$I$2), 3, IF( OR(F5=$H$2, G5=$I$2), 1, 0 ) ) )) -> 4 | J5: =D5+H5 -> 7 | K5: 2 | L5: 0 | M5: =IF(AND(K5="",L5=""),0,IF(AND(K5=$M$2,L5=$N$2),5,IF(AND(SIGN(K5-L5)=SIGN($M$2-$N$2),OR(K5=$M$2,L5=$N$2)),4,IF(SIGN(K5-L5)=SIGN($M$2-$N$2),3,IF(OR(K5=$M$2,L5=$N$2),1,0))))) -> 0 | O5: 1 | P5: 2 | Q5: =IF(AND(O5="",P5=""),0,IF(AND(O5=$Q$2,P5=$R$2),5,IF(AND(SIGN(O5-P5)=SIGN($Q$2-$R$2),OR(O5=$Q$2,P5=$R$2)),4,IF(SIGN(O5-P5)=SIGN($Q$2-$R$2),3,IF(OR(O5=$Q$2,P5=$R$2),1,0))))) -> 0 | S5: =M5+Q5 -> 0 | T5: 0 | U5: 2 | V5: =IF(AND(T5="",U5=""),0,IF(AND(T5=$V$2,U5=$W$2),5,IF(AND(SIGN(T5-U5)=SIGN($V$2-$W$2),OR(T5=$V$2,U5=$W$2)),4,IF(SIGN(T5-U5)=SIGN($V$2-$W$2),3,IF(OR(T5=$V$2,U5=$W$2),1,0))))) -> 0 | X5: 3 | Y5: 1 | Z5: =IF(AND(X5="",Y5=""),0,IF(AND(X5=$Z$2,Y5=$AA$2),5,IF(AND(SIGN(X5-Y5)=SIGN($Z$2-$AA$2),OR(X5=$Z$2,Y5=$AA$2)),4,IF(SIGN(X5-Y5)=SIGN($Z$2-$AA$2),3,IF(OR(X5=$Z$2,Y5=$AA$2),1,0))))) -> 1 | AB5: 0 | AC5: 2 | AD5: =IF(AND(AB5="",AC5=""),0,IF(AND(AB5=$AD$2,AC5=$AE$2),5,IF(AND(SIGN(AB5-AC5)=SIGN($AD$2-$AE$2),OR(AB5=$AD$2,AC5=$AE$2)),4,IF(SIGN(AB5-AC5)=SIGN($AD$2-$AE$2),3,IF(OR(AB5=$AD$2,AC5=$AE$2),1,0))))) -> 4 | AF5: 0 | AG5: 2 | AH5: =IF(AND(AF5="",AG5=""),0,IF(AND(AF5=$AH$2,AG5=$AI$2),5,IF(AND(SIGN(AF5-AG5)=SIGN($AH$2-$AI$2),OR(AF5=$AH$2,AG5=$AI$2)),4,IF(SIGN(AF5-AG5)=SIGN($AH$2-$AI$2),3,IF(OR(AF5=$AH$2,AG5=$AI$2),1,0))))) -> 0 | AJ5: =V5+Z5+AD5+AH5 -> 5 | AK5: 6 | AL5: 0 | AM5: =IF(AND(AK5="",AL5=""),0,IF(AND(AK5=$AM$2,AL5=$AN$2),5,IF(AND(SIGN(AK5-AL5)=SIGN($AM$2-$AN$2),OR(AK5=$AM$2,AL5=$AN$2)),4,IF(SIGN(AK5-AL5)=SIGN($AM$2-$AN$2),3,IF(OR(AK5=$AM$2,AL5=$AN$2),1,0))))) -> 3 | AO5: 2 | AP5: 2 | AQ5: =IF(AND(AO5="",AP5=""),0,IF(AND(AO5=$AQ$2,AP5=$AR$2),5,IF(AND(SIGN(AO5-AP5)=SIGN($AQ$2-$AR$2),OR(AO5=$AQ$2,AP5=$AR$2)),4,IF(SIGN(AO5-AP5)=SIGN($AQ$2-$AR$2),3,IF(OR(AO5=$AQ$2,AP5=$AR$2),1,0))))) -> 5 | AS5: 2 | AT5: 1 | AU5: =IF(AND(AS5="",AT5=""),0,IF(AND(AS5=$AU$2,AT5=$AV$2),5,IF(AND(SIGN(AS5-AT5)=SIGN($AU$2-$AV$2),OR(AS5=$AU$2,AT5=$AV$2)),4,IF(SIGN(AS5-AT5)=SIGN($AU$2-$AV$2),3,IF(OR(AS5=$AU$2,AT5=$AV$2),1,0))))) -> 3 | AW5: 3 | AX5: 0 | AY5: =IF(AND(AW5="",AX5=""),0,IF(AND(AW5=$AY$2,AX5=$AZ$2),5,IF(AND(SIGN(AW5-AX5)=SIGN($AY$2-$AZ$2),OR(AW5=$AY$2,AX5=$AZ$2)),4,IF(SIGN(AW5-AX5)=SIGN($AY$2-$AZ$2),3,IF(OR(AW5=$AY$2,AX5=$AZ$2),1,0))))) -> 3 | BA5: =AM5+AQ5+AU5+AY5 -> 14 | BB5: 5 | BC5: 0 | BD5: =IF(AND(BB5="",BC5=""),0,IF(AND(BB5=$BD$2,BC5=$BE$2),5,IF(AND(SIGN(BB5-BC5)=SIGN($BD$2-$BE$2),OR(BB5=$BD$2,BC5=$BE$2)),4,IF(SIGN(BB5-BC5)=SIGN($BD$2-$BE$2),3,IF(OR(BB5=$BD$2,BC5=$BE$2),1,0))))) -> 1 | BF5: 2 | BG5: 1 | BH5: =IF(AND(BF5="",BG5=""),0,IF(AND(BF5=$BH$2,BG5=$BI$2),5,IF(AND(SIGN(BF5-BG5)=SIGN($BH$2-$BI$2),OR(BF5=$BH$2,BG5=$BI$2)),4,IF(SIGN(BF5-BG5)=SIGN($BH$2-$BI$2),3,IF(OR(BF5=$BH$2,BG5=$BI$2),1,0))))) -> 1 | BJ5: 0 | BK5: 2 | BL5: =IF(AND(BJ5="",BK5=""),0,IF(AND(BJ5=$BL$2,BK5=$BM$2),5,IF(AND(SIGN(BJ5-BK5)=SIGN($BL$2-$BM$2),OR(BJ5=$BL$2,BK5=$BM$2)),4,IF(SIGN(BJ5-BK5)=SIGN($BL$2-$BM$2),3,IF(OR(BJ5=$BL$2,BK5=$BM$2),1,0))))) -> 0 | BN5: 0 | BO5: 3 | BP5: =IF(AND(BN5="",BO5=""),0,IF(AND(BN5=$BP$2,BO5=$BQ$2),5,IF(AND(SIGN(BN5-BO5)=SIGN($BP$2-$BQ$2),OR(BN5=$BP$2,BO5=$BQ$2)),4,IF(SIGN(BN5-BO5)=SIGN($BP$2-$BQ$2),3,IF(OR(BN5=$BP$2,BO5=$BQ$2),1,0))))) -> 0 | BR5: =BD5+BH5+BL5+BP5 -> 2 | BS5: 4 | BT5: 0 | BU5: =IF(AND(BS5="",BT5=""),0,IF(AND(BS5=$BU$2,BT5=$BV$2),5,IF(AND(SIGN(BS5-BT5)=SIGN($BU$2-$BV$2),OR(BS5=$BU$2,BT5=$BV$2)),4,IF(SIGN(BS5-BT5)=SIGN($BU$2-$BV$2),3,IF(OR(BS5=$BU$2,BT5=$BV$2),1,0))))) -> 3 | BW5: 0 | BX5: 4 | BY5: =IF(AND(BW5="",BX5=""),0,IF(AND(BW5=$BY$2,BX5=$BZ$2),5,IF(AND(SIGN(BW5-BX5)=SIGN($BY$2-$BZ$2),OR(BW5=$BY$2,BX5=$BZ$2)),4,IF(SIGN(BW5-BX5)=SIGN($BY$2-$BZ$2),3,IF(OR(BW5=$BY$2,BX5=$BZ$2),1,0))))) -> 4 | CA5: 5 | CB5: 0 | CC5: =IF(AND(CA5="",CB5=""),0,IF(AND(CA5=$CC$2,CB5=$CD$2),5,IF(AND(SIGN(CA5-CB5)=SIGN($CC$2-$CD$2),OR(CA5=$CC$2,CB5=$CD$2)),4,IF(SIGN(CA5-CB5)=SIGN($CC$2-$CD$2),3,IF(OR(CA5=$CC$2,CB5=$CD$2),1,0))))) -> 4 | CE5: 2 | CF5: 0 | CG5: =IF(AND(CE5="",CF5=""),0,IF(AND(CE5=$CG$2,CF5=$CH$2),5,IF(AND(SIGN(CE5-CF5)=SIGN($CG$2-$CH$2),OR(CE5=$CG$2,CF5=$CH$2)),4,IF(SIGN(CE5-CF5)=SIGN($CG$2-$CH$2),3,IF(OR(CE5=$CG$2,CF5=$CH$2),1,0))))) -> 3 | CI5: =BU5+BY5+CC5+CG5 -> 14 | CJ5: 3 | CK5: 0 | CL5: =IF(AND(CJ5="",CK5=""),0,IF(AND(CJ5=$CL$2,CK5=$CM$2),5,IF(AND(SIGN(CJ5-CK5)=SIGN($CL$2-$CM$2),OR(CJ5=$CL$2,CK5=$CM$2)),4,IF(SIGN(CJ5-CK5)=SIGN($CL$2-$CM$2),3,IF(OR(CJ5=$CL$2,CK5=$CM$2),1,0))))) -> 0 | CN5: 2 | CO5: 1 | CP5: =IF(AND(CN5="",CO5=""),0,IF(AND(CN5=$CP$2,CO5=$CQ$2),5,IF(AND(SIGN(CN5-CO5)=SIGN($CP$2-$CQ$2),OR(CN5=$CP$2,CO5=$CQ$2)),4,IF(SIGN(CN5-CO5)=SIGN($CP$2-$CQ$2),3,IF(OR(CN5=$CP$2,CO5=$CQ$2),1,0))))) -> 3 | CR5: 3 | CS5: 0 | CT5: =IF(AND(CR5="",CS5=""),0,IF(AND(CR5=$CT$2,CS5=$CU$2),5,IF(AND(SIGN(CR5-CS5)=SIGN($CT$2-$CU$2),OR(CR5=$CT$2,CS5=$CU$2)),4,IF(SIGN(CR5-CS5)=SIGN($CT$2-$CU$2),3,IF(OR(CR5=$CT$2,CS5=$CU$2),1,0))))) -> 4 | CV5: 0 | CW5: 4 | CX5: =IF(AND(CV5="",CW5=""),0,IF(AND(CV5=$CX$2,CW5=$CY$2),5,IF(AND(SIGN(CV5-CW5)=SIGN($CX$2-$CY$2),OR(CV5=$CX$2,CW5=$CY$2)),4,IF(SIGN(CV5-CW5)=SIGN($CX$2-$CY$2),3,IF(OR(CV5=$CX$2,CW5=$CY$2),1,0))))) -> 3 | CZ5: =CL5+CP5+CT5+CX5 -> 10 | DA5: 3 | DB5: 1 | DC5: =IF(AND(DA5="",DB5=""),0,IF(AND(DA5=$DC$2,DB5=$DD$2),5,IF(AND(SIGN(DA5-DB5)=SIGN($DC$2-$DD$2),OR(DA5=$DC$2,DB5=$DD$2)),4,IF(SIGN(DA5-DB5)=SIGN($DC$2-$DD$2),3,IF(OR(DA5=$DC$2,DB5=$DD$2),1,0))))) -> 1 | DE5: 2 | DF5: 0 | DG5: =IF(AND(DE5="",DF5=""),0,IF(AND(DE5=$DG$2,DF5=$DH$2),5,IF(AND(SIGN(DE5-DF5)=SIGN($DG$2-$DH$2),OR(DE5=$DG$2,DF5=$DH$2)),4,IF(SIGN(DE5-DF5)=SIGN($DG$2-$DH$2),3,IF(OR(DE5=$DG$2,DF5=$DH$2),1,0))))) -> 3 | DI5: 2 | DJ5: 1 | DK5: =IF(AND(DI5="",DJ5=""),0,IF(AND(DI5=$DK$2,DJ5=$DL$2),5,IF(AND(SIGN(DI5-DJ5)=SIGN($DK$2-$DL$2),OR(DI5=$DK$2,DJ5=$DL$2)),4,IF(SIGN(DI5-DJ5)=SIGN($DK$2-$DL$2),3,IF(OR(DI5=$DK$2,DJ5=$DL$2),1,0))))) -> 3 | DM5: 1 | DN5: 2 | DO5: =IF(AND(DM5="",DN5=""),0,IF(AND(DM5=$DO$2,DN5=$DP$2),5,IF(AND(SIGN(DM5-DN5)=SIGN($DO$2-$DP$2),OR(DM5=$DO$2,DN5=$DP$2)),4,IF(SIGN(DM5-DN5)=SIGN($DO$2-$DP$2),3,IF(OR(DM5=$DO$2,DN5=$DP$2),1,0))))) -> 1 | DQ5: =DC5+DG5+DK5+DO5 -> 8 | DR5: 5 | DS5: 0 | DT5: =IF(AND(DR5="",DS5=""),0,IF(AND(DR5=$DT$2,DS5=$DU$2),5,IF(AND(SIGN(DR5-DS5)=SIGN($DT$2-$DU$2),OR(DR5=$DT$2,DS5=$DU$2)),4,IF(SIGN(DR5-DS5)=SIGN($DT$2-$DU$2),3,IF(OR(DR5=$DT$2,DS5=$DU$2),1,0))))) -> 4 | DV5: 2 | DW5: 0 | DX5: =IF(AND(DV5="",DW5=""),0,IF(AND(DV5=$DX$2,DW5=$DY$2),5,IF(AND(SIGN(DV5-DW5)=SIGN($DX$2-$DY$2),OR(DV5=$DX$2,DW5=$DY$2)),4,IF(SIGN(DV5-DW5)=SIGN($DX$2-$DY$2),3,IF(OR(DV5=$DX$2,DW5=$DY$2),1,0))))) -> 0 | DZ5: 6 | EA5: 0 | EB5: =IF(AND(DZ5="",EA5=""),0,IF(AND(DZ5=$EB$2,EA5=$EC$2),5,IF(AND(SIGN(DZ5-EA5)=SIGN($EB$2-$EC$2),OR(DZ5=$EB$2,EA5=$EC$2)),4,IF(SIGN(DZ5-EA5)=SIGN($EB$2-$EC$2),3,IF(OR(DZ5=$EB$2,EA5=$EC$2),1,0))))) -> 4 | ED5: 0 | EE5: 2 | EF5: =IF(AND(ED5="",EE5=""),0,IF(AND(ED5=$EF$2,EE5=$EG$2),5,IF(AND(SIGN(ED5-EE5)=SIGN($EF$2-$EG$2),OR(ED5=$EF$2,EE5=$EG$2)),4,IF(SIGN(ED5-EE5)=SIGN($EF$2-$EG$2),3,IF(OR(ED5=$EF$2,EE5=$EG$2),1,0))))) -> 4 | EH5: =DT5+DX5+EB5+EF5 -> 12 | EI5: 2 | EJ5: 1 | EK5: =IF(AND(EI5="",EJ5=""),0,IF(AND(EI5=$EK$2,EJ5=$EL$2),5,IF(AND(SIGN(EI5-EJ5)=SIGN($EK$2-$EL$2),OR(EI5=$EK$2,EJ5=$EL$2)),4,IF(SIGN(EI5-EJ5)=SIGN($EK$2-$EL$2),3,IF(OR(EI5=$EK$2,EJ5=$EL$2),1,0))))) -> 4 | EM5: 3 | EN5: 0 | EO5: =IF(AND(EM5="",EN5=""),0,IF(AND(EM5=$EO$2,EN5=$EP$2),5,IF(AND(SIGN(EM5-EN5)=SIGN($EO$2-$EP$2),OR(EM5=$EO$2,EN5=$EP$2)),4,IF(SIGN(EM5-EN5)=SIGN($EO$2-$EP$2),3,IF(OR(EM5=$EO$2,EN5=$EP$2),1,0))))) -> 3 | EQ5: 2 | ER5: 0 | ES5: =IF(AND(EQ5="",ER5=""),0,IF(AND(EQ5=$ES$2,ER5=$ET$2),5,IF(AND(SIGN(EQ5-ER5)=SIGN($ES$2-$ET$2),OR(EQ5=$ES$2,ER5=$ET$2)),4,IF(SIGN(EQ5-ER5)=SIGN($ES$2-$ET$2),3,IF(OR(EQ5=$ES$2,ER5=$ET$2),1,0))))) -> 1 | EU5: 0 | EV5: 3 | EW5: =IF(AND(EU5="",EV5=""),0,IF(AND(EU5=$EW$2,EV5=$EX$2),5,IF(AND(SIGN(EU5-EV5)=SIGN($EW$2-$EX$2),OR(EU5=$EW$2,EV5=$EX$2)),4,IF(SIGN(EU5-EV5)=SIGN($EW$2-$EX$2),3,IF(OR(EU5=$EW$2,EV5=$EX$2),1,0))))) -> 4 | EY5: 6 | EZ5: 2 | FA5: 0 | FD5: 2 | FE5: 1 | FH5: 2 | FI5: 0 | FL5: 0 | FM5: 2 | FP5: =FB5+FF5+FJ5+FN5 -> 0 | FS5: =IF(AND(FQ5="",FR5=""),0,IF(AND(FQ5=$FS$2,FR5=$FT$2),5,IF(AND(SIGN(FQ5-FR5)=SIGN($FS$2-$FT$2),OR(FQ5=$FS$2,FR5=$FT$2)),4,IF(SIGN(FQ5-FR5)=SIGN($FS$2-$FT$2),3,IF(OR(FQ5=$FS$2,FR5=$FT$2),1,0))))) -> 0 | FW5: =IF(AND(FU5="",FV5=""),0,IF(AND(FU5=$FW$2,FV5=$FX$2),5,IF(AND(SIGN(FU5-FV5)=SIGN($FW$2-$FX$2),OR(FU5=$FW$2,FV5=$FX$2)),4,IF(SIGN(FU5-FV5)=SIGN($FW$2-$FX$2),3,IF(OR(FU5=$FW$2,FV5=$FX$2),1,0))))) -> 0 | GA5: =IF(AND(FY5="",FZ5=""),0,IF(AND(FY5=$GA$2,FZ5=$GB$2),5,IF(AND(SIGN(FY5-FZ5)=SIGN($GA$2-$GB$2),OR(FY5=$GA$2,FZ5=$GB$2)),4,IF(SIGN(FY5-FZ5)=SIGN($GA$2-$GB$2),3,IF(OR(FY5=$GA$2,FZ5=$GB$2),1,0))))) -> 0 | GE5: =IF(AND(GC5="",GD5=""),0,IF(AND(GC5=$GE$2,GD5=$GF$2),5,IF(AND(SIGN(GC5-GD5)=SIGN($GE$2-$GF$2),OR(GC5=$GE$2,GD5=$GF$2)),4,IF(SIGN(GC5-GD5)=SIGN($GE$2-$GF$2),3,IF(OR(GC5=$GE$2,GD5=$GF$2),1,0))))) -> 0 | GG5: =FS5+FW5+GA5+GE5 -> 0 | GJ5: =IF(AND(GH5="",GI5=""),0,IF(AND(GH5=$GJ$2,GI5=$GK$2),5,IF(AND(SIGN(GH5-GI5)=SIGN($GJ$2-$GK$2),OR(GH5=$GJ$2,GI5=$GK$2)),4,IF(SIGN(GH5-GI5)=SIGN($GJ$2-$GK$2),3,IF(OR(GH5=$GJ$2,GI5=$GK$2),1,0))))) -> 0 | GN5: =IF(AND(GL5="",GM5=""),0,IF(AND(GL5=$GN$2,GM5=$GO$2),5,IF(AND(SIGN(GL5-GM5)=SIGN($GN$2-$GO$2),OR(GL5=$GN$2,GM5=$GO$2)),4,IF(SIGN(GL5-GM5)=SIGN($GN$2-$GO$2),3,IF(OR(GL5=$GN$2,GM5=$GO$2),1,0))))) -> 0 | GR5: =IF(AND(GP5="",GQ5=""),0,IF(AND(GP5=$GR$2,GQ5=$GS$2),5,IF(AND(SIGN(GP5-GQ5)=SIGN($GR$2-$GS$2),OR(GP5=$GR$2,GQ5=$GS$2)),4,IF(SIGN(GP5-GQ5)=SIGN($GR$2-$GS$2),3,IF(OR(GP5=$GR$2,GQ5=$GS$2),1,0))))) -> 0 | GV5: =IF(AND(GT5="",GU5=""),0,IF(AND(GT5=$GV$2,GU5=$GW$2),5,IF(AND(SIGN(GT5-GU5)=SIGN($GV$2-$GW$2),OR(GT5=$GV$2,GU5=$GW$2)),4,IF(SIGN(GT5-GU5)=SIGN($GV$2-$GW$2),3,IF(OR(GT5=$GV$2,GU5=$GW$2),1,0))))) -> 0 | GX5: =GJ5+GN5+GR5+GV5 -> 0 | HA5: =IF(AND(GY5="",GZ5=""),0,IF(AND(GY5=$HA$2,GZ5=$HB$2),5,IF(AND(SIGN(GY5-GZ5)=SIGN($HA$2-$HB$2),OR(GY5=$HA$2,GZ5=$HB$2)),4,IF(SIGN(GY5-GZ5)=SIGN($HA$2-$HB$2),3,IF(OR(GY5=$HA$2,GZ5=$HB$2),1,0))))) -> 0 | HE5: =IF(AND(HC5="",HD5=""),0,IF(AND(HC5=$HE$2,HD5=$HF$2),5,IF(AND(SIGN(HC5-HD5)=SIGN($HE$2-$HF$2),OR(HC5=$HE$2,HD5=$HF$2)),4,IF(SIGN(HC5-HD5)=SIGN($HE$2-$HF$2),3,IF(OR(HC5=$HE$2,HD5=$HF$2),1,0))))) -> 0 | HI5: =IF(AND(HG5="",HH5=""),0,IF(AND(HG5=$HI$2,HH5=$HJ$2),5,IF(AND(SIGN(HG5-HH5)=SIGN($HI$2-$HJ$2),OR(HG5=$HI$2,HH5=$HJ$2)),4,IF(SIGN(HG5-HH5)=SIGN($HI$2-$HJ$2),3,IF(OR(HG5=$HI$2,HH5=$HJ$2),1,0))))) -> 0 | HM5: =IF(AND(HK5="",HL5=""),0,IF(AND(HK5=$HM$2,HL5=$HN$2),5,IF(AND(SIGN(HK5-HL5)=SIGN($HM$2-$HN$2),OR(HK5=$HM$2,HL5=$HN$2)),4,IF(SIGN(HK5-HL5)=SIGN($HM$2-$HN$2),3,IF(OR(HK5=$HM$2,HL5=$HN$2),1,0))))) -> 0 | HQ5: =IF(AND(HO5="",HP5=""),0,IF(AND(HO5=$HQ$2,HP5=$HR$2),5,IF(AND(SIGN(HO5-HP5)=SIGN($HQ$2-$HR$2),OR(HO5=$HQ$2,HP5=$HR$2)),4,IF(SIGN(HO5-HP5)=SIGN($HQ$2-$HR$2),3,IF(OR(HO5=$HQ$2,HP5=$HR$2),1,0))))) -> 0 | HU5: =IF(AND(HS5="",HT5=""),0,IF(AND(HS5=$HU$2,HT5=$HV$2),5,IF(AND(SIGN(HS5-HT5)=SIGN($HU$2-$HV$2),OR(HS5=$HU$2,HT5=$HV$2)),4,IF(SIGN(HS5-HT5)=SIGN($HU$2-$HV$2),3,IF(OR(HS5=$HU$2,HT5=$HV$2),1,0))))) -> 0 | HW5: =HI5+HM5+HQ5+HU5+HE5+HA5 -> 0 | HZ5: =IF(AND(HX5="",HY5=""),0,IF(AND(HX5=$HZ$2,HY5=$IA$2),5,IF(AND(SIGN(HX5-HY5)=SIGN($HZ$2-$IA$2),OR(HX5=$HZ$2,HY5=$IA$2)),4,IF(SIGN(HX5-HY5)=SIGN($HZ$2-$IA$2),3,IF(OR(HX5=$HZ$2,HY5=$IA$2),1,0))))) -> 0 | ID5: =IF(AND(IB5="",IC5=""),0,IF(AND(IB5=$ID$2,IC5=$IE$2),5,IF(AND(SIGN(IB5-IC5)=SIGN($ID$2-$IE$2),OR(IB5=$ID$2,IC5=$IE$2)),4,IF(SIGN(IB5-IC5)=SIGN($ID$2-$IE$2),3,IF(OR(IB5=$ID$2,IC5=$IE$2),1,0))))) -> 0 | IH5: =IF(AND(IF5="",IG5=""),0,IF(AND(IF5=$IH$2,IG5=$II$2),5,IF(AND(SIGN(IF5-IG5)=SIGN($IH$2-$II$2),OR(IF5=$IH$2,IG5=$II$2)),4,IF(SIGN(IF5-IG5)=SIGN($IH$2-$II$2),3,IF(OR(IF5=$IH$2,IG5=$II$2),1,0))))) -> 0 | IL5: =IF(AND(IJ5="",IK5=""),0,IF(AND(IJ5=$IL$2,IK5=$IM$2),5,IF(AND(SIGN(IJ5-IK5)=SIGN($IL$2-$IM$2),OR(IJ5=$IL$2,IK5=$IM$2)),4,IF(SIGN(IJ5-IK5)=SIGN($IL$2-$IM$2),3,IF(OR(IJ5=$IL$2,IK5=$IM$2),1,0))))) -> 0 | IP5: =IF(AND(IN5="",IO5=""),0,IF(AND(IN5=$IP$2,IO5=$IQ$2),5,IF(AND(SIGN(IN5-IO5)=SIGN($IP$2-$IQ$2),OR(IN5=$IP$2,IO5=$IQ$2)),4,IF(SIGN(IN5-IO5)=SIGN($IP$2-$IQ$2),3,IF(OR(IN5=$IP$2,IO5=$IQ$2),1,0))))) -> 0 | IT5: =IF(AND(IR5="",IS5=""),0,IF(AND(IR5=$IT$2,IS5=$IU$2),5,IF(AND(SIGN(IR5-IS5)=SIGN($IT$2-$IU$2),OR(IR5=$IT$2,IS5=$IU$2)),4,IF(SIGN(IR5-IS5)=SIGN($IT$2-$IU$2),3,IF(OR(IR5=$IT$2,IS5=$IU$2),1,0))))) -> 0 | IV5: =IH5+IL5+IP5+IT5+ID5+HZ5 -> 0 | IY5: =IF(AND(IW5="",IX5=""),0,IF(AND(IW5=$IY$2,IX5=$IZ$2),5,IF(AND(SIGN(IW5-IX5)=SIGN($IY$2-$IZ$2),OR(IW5=$IY$2,IX5=$IZ$2)),4,IF(SIGN(IW5-IX5)=SIGN($IY$2-$IZ$2),3,IF(OR(IW5=$IY$2,IX5=$IZ$2),1,0))))) -> 0 | JC5: =IF(AND(JA5="",JB5=""),0,IF(AND(JA5=$JC$2,JB5=$JD$2),5,IF(AND(SIGN(JA5-JB5)=SIGN($JC$2-$JD$2),OR(JA5=$JC$2,JB5=$JD$2)),4,IF(SIGN(JA5-JB5)=SIGN($JC$2-$JD$2),3,IF(OR(JA5=$JC$2,JB5=$JD$2),1,0))))) -> 0 | JG5: =IF(AND(JE5="",JF5=""),0,IF(AND(JE5=$JG$2,JF5=$JH$2),5,IF(AND(SIGN(JE5-JF5)=SIGN($JG$2-$JH$2),OR(JE5=$JG$2,JF5=$JH$2)),4,IF(SIGN(JE5-JF5)=SIGN($JG$2-$JH$2),3,IF(OR(JE5=$JG$2,JF5=$JH$2),1,0))))) -> 0 | JK5: =IF(AND(JI5="",JJ5=""),0,IF(AND(JI5=$JK$2,JJ5=$JL$2),5,IF(AND(SIGN(JI5-JJ5)=SIGN($JK$2-$JL$2),OR(JI5=$JK$2,JJ5=$JL$2)),4,IF(SIGN(JI5-JJ5)=SIGN($JK$2-$JL$2),3,IF(OR(JI5=$JK$2,JJ5=$JL$2),1,0))))) -> 0 | JO5: =IF(AND(JM5="",JN5=""),0,IF(AND(JM5=$JO$2,JN5=$JP$2),5,IF(AND(SIGN(JM5-JN5)=SIGN($JO$2-$JP$2),OR(JM5=$JO$2,JN5=$JP$2)),4,IF(SIGN(JM5-JN5)=SIGN($JO$2-$JP$2),3,IF(OR(JM5=$JO$2,JN5=$JP$2),1,0))))) -> 0 | JS5: =IF(AND(JQ5="",JR5=""),0,IF(AND(JQ5=$JS$2,JR5=$JT$2),5,IF(AND(SIGN(JQ5-JR5)=SIGN($JS$2-$JT$2),OR(JQ5=$JS$2,JR5=$JT$2)),4,IF(SIGN(JQ5-JR5)=SIGN($JS$2-$JT$2),3,IF(OR(JQ5=$JS$2,JR5=$JT$2),1,0))))) -> 0 | JU5: =JG5+JK5+JO5+JS5+JC5+IY5 -> 0 | JX5: =IF(AND(JV5="",JW5=""),0,IF(AND(JV5=$JX$2,JW5=$JY$2),5,IF(AND(SIGN(JV5-JW5)=SIGN($JX$2-$JY$2),OR(JV5=$JX$2,JW5=$JY$2)),4,IF(SIGN(JV5-JW5)=SIGN($JX$2-$JY$2),3,IF(OR(JV5=$JX$2,JW5=$JY$2),1,0))))) -> 0 | KB5: =IF(AND(JZ5="",KA5=""),0,IF(AND(JZ5=$KB$2,KA5=$KC$2),5,IF(AND(SIGN(JZ5-KA5)=SIGN($KB$2-$KC$2),OR(JZ5=$KB$2,KA5=$KC$2)),4,IF(SIGN(JZ5-KA5)=SIGN($KB$2-$KC$2),3,IF(OR(JZ5=$KB$2,KA5=$KC$2),1,0))))) -> 0 | KF5: =IF(AND(KD5="",KE5=""),0,IF(AND(KD5=$KF$2,KE5=$KG$2),5,IF(AND(SIGN(KD5-KE5)=SIGN($KF$2-$KG$2),OR(KD5=$KF$2,KE5=$KG$2)),4,IF(SIGN(KD5-KE5)=SIGN($KF$2-$KG$2),3,IF(OR(KD5=$KF$2,KE5=$KG$2),1,0))))) -> 0 | KJ5: =IF(AND(KH5="",KI5=""),0,IF(AND(KH5=$KJ$2,KI5=$KK$2),5,IF(AND(SIGN(KH5-KI5)=SIGN($KJ$2-$KK$2),OR(KH5=$KJ$2,KI5=$KK$2)),4,IF(SIGN(KH5-KI5)=SIGN($KJ$2-$KK$2),3,IF(OR(KH5=$KJ$2,KI5=$KK$2),1,0))))) -> 0 | KN5: =IF(AND(KL5="",KM5=""),0,IF(AND(KL5=$KN$2,KM5=$KO$2),5,IF(AND(SIGN(KL5-KM5)=SIGN($KN$2-$KO$2),OR(KL5=$KN$2,KM5=$KO$2)),4,IF(SIGN(KL5-KM5)=SIGN($KN$2-$KO$2),3,IF(OR(KL5=$KN$2,KM5=$KO$2),1,0))))) -> 0 | KR5: =IF(AND(KP5="",KQ5=""),0,IF(AND(KP5=$KR$2,KQ5=$KS$2),5,IF(AND(SIGN(KP5-KQ5)=SIGN($KR$2-$KS$2),OR(KP5=$KR$2,KQ5=$KS$2)),4,IF(SIGN(KP5-KQ5)=SIGN($KR$2-$KS$2),3,IF(OR(KP5=$KR$2,KQ5=$KS$2),1,0))))) -> 0 | KT5: =KF5+KJ5+KN5+KR5+KB5+JX5 -> 0 | KW5: =IF(AND(KU5="",KV5=""),0,IF(AND(KU5=$KW$2,KV5=$KX$2),5,IF(AND(SIGN(KU5-KV5)=SIGN($KW$2-$KX$2),OR(KU5=$KW$2,KV5=$KX$2)),4,IF(SIGN(KU5-KV5)=SIGN($KW$2-$KX$2),3,IF(OR(KU5=$KW$2,KV5=$KX$2),1,0))))) -> 0 | KY5: =KW5 -> 0 | LB5: =IF(AND(KZ5="",LA5=""),0,IF(AND(KZ5=$LB$2,LA5=$LC$2),5,IF(AND(SIGN(KZ5-LA5)=SIGN($LB$2-$LC$2),OR(KZ5=$LB$2,LA5=$LC$2)),4,IF(SIGN(KZ5-LA5)=SIGN($LB$2-$LC$2),3,IF(OR(KZ5=$LB$2,LA5=$LC$2),1,0))))) -> 0 | LF5: =IF(AND(LD5="",LE5=""),0,IF(AND(LD5=$LF$2,LE5=$LG$2),5,IF(AND(SIGN(LD5-LE5)=SIGN($LF$2-$LG$2),OR(LD5=$LF$2,LE5=$LG$2)),4,IF(SIGN(LD5-LE5)=SIGN($LF$2-$LG$2),3,IF(OR(LD5=$LF$2,LE5=$LG$2),1,0))))) -> 0 | LJ5: =IF(AND(LH5="",LI5=""),0,IF(AND(LH5=$LJ$2,LI5=$LK$2),5,IF(AND(SIGN(LH5-LI5)=SIGN($LJ$2-$LK$2),OR(LH5=$LJ$2,LI5=$LK$2)),4,IF(SIGN(LH5-LI5)=SIGN($LJ$2-$LK$2),3,IF(OR(LH5=$LJ$2,LI5=$LK$2),1,0))))) -> 0 | LL5: =LB5+LF5+LJ5 -> 0 | LO5: =IF(AND(LM5="",LN5=""),0,IF(AND(LM5=$LO$2,LN5=$LP$2),5,IF(AND(SIGN(LM5-LN5)=SIGN($LO$2-$LP$2),OR(LM5=$LO$2,LN5=$LP$2)),4,IF(SIGN(LM5-LN5)=SIGN($LO$2-$LP$2),3,IF(OR(LM5=$LO$2,LN5=$LP$2),1,0))))) -> 0 | LS5: =IF(AND(LQ5="",LR5=""),0,IF(AND(LQ5=$LS$2,LR5=$LT$2),5,IF(AND(SIGN(LQ5-LR5)=SIGN($LS$2-$LT$2),OR(LQ5=$LS$2,LR5=$LT$2)),4,IF(SIGN(LQ5-LR5)=SIGN($LS$2-$LT$2),3,IF(OR(LQ5=$LS$2,LR5=$LT$2),1,0))))) -> 0 | LW5: =IF(AND(LU5="",LV5=""),0,IF(AND(LU5=$LW$2,LV5=$LX$2),5,IF(AND(SIGN(LU5-LV5)=SIGN($LW$2-$LX$2),OR(LU5=$LW$2,LV5=$LX$2)),4,IF(SIGN(LU5-LV5)=SIGN($LW$2-$LX$2),3,IF(OR(LU5=$LW$2,LV5=$LX$2),1,0))))) -> 0 | LY5: =LO5+LS5+LW5 -> 0 | MB5: =IF(AND(LZ5="",MA5=""),0,IF(AND(LZ5=$MB$2,MA5=$MC$2),5,IF(AND(SIGN(LZ5-MA5)=SIGN($MB$2-$MC$2),OR(LZ5=$MB$2,MA5=$MC$2)),4,IF(SIGN(LZ5-MA5)=SIGN($MB$2-$MC$2),3,IF(OR(LZ5=$MB$2,MA5=$MC$2),1,0))))) -> 0 | MF5: =IF(AND(MD5="",ME5=""),0,IF(AND(MD5=$MF$2,ME5=$MG$2),5,IF(AND(SIGN(MD5-ME5)=SIGN($MF$2-$MG$2),OR(MD5=$MF$2,ME5=$MG$2)),4,IF(SIGN(MD5-ME5)=SIGN($MF$2-$MG$2),3,IF(OR(MD5=$MF$2,ME5=$MG$2),1,0))))) -> 0 | MJ5: =IF(AND(MH5="",MI5=""),0,IF(AND(MH5=$MJ$2,MI5=$MK$2),5,IF(AND(SIGN(MH5-MI5)=SIGN($MJ$2-$MK$2),OR(MH5=$MJ$2,MI5=$MK$2)),4,IF(SIGN(MH5-MI5)=SIGN($MJ$2-$MK$2),3,IF(OR(MH5=$MJ$2,MI5=$MK$2),1,0))))) -> 0 | ML5: =MB5+MF5+MJ5 -> 0 | MO5: =IF(AND(MM5="",MN5=""),0,IF(AND(MM5=$MO$2,MN5=$MP$2),5,IF(AND(SIGN(MM5-MN5)=SIGN($MO$2-$MP$2),OR(MM5=$MO$2,MN5=$MP$2)),4,IF(SIGN(MM5-MN5)=SIGN($MO$2-$MP$2),3,IF(OR(MM5=$MO$2,MN5=$MP$2),1,0))))) -> 0 | MS5: =IF(AND(MQ5="",MR5=""),0,IF(AND(MQ5=$MS$2,MR5=$MT$2),5,IF(AND(SIGN(MQ5-MR5)=SIGN($MS$2-$MT$2),OR(MQ5=$MS$2,MR5=$MT$2)),4,IF(SIGN(MQ5-MR5)=SIGN($MS$2-$MT$2),3,IF(OR(MQ5=$MS$2,MR5=$MT$2),1,0))))) -> 0 | MW5: =IF(AND(MU5="",MV5=""),0,IF(AND(MU5=$MW$2,MV5=$MX$2),5,IF(AND(SIGN(MU5-MV5)=SIGN($MW$2-$MX$2),OR(MU5=$MW$2,MV5=$MX$2)),4,IF(SIGN(MU5-MV5)=SIGN($MW$2-$MX$2),3,IF(OR(MU5=$MW$2,MV5=$MX$2),1,0))))) -> 0 | MY5: =MO5+MS5+MW5 -> 0 | NB5: =IF(AND(MZ5="",NA5=""),0,IF(AND(MZ5=$NB$2,NA5=$NC$2),5,IF(AND(SIGN(MZ5-NA5)=SIGN($NB$2-$NC$2),OR(MZ5=$NB$2,NA5=$NC$2)),4,IF(SIGN(MZ5-NA5)=SIGN($NB$2-$NC$2),3,IF(OR(MZ5=$NB$2,NA5=$NC$2),1,0))))) -> 0 | NF5: =IF(AND(ND5="",NE5=""),0,IF(AND(ND5=$NF$2,NE5=$NG$2),5,IF(AND(SIGN(ND5-NE5)=SIGN($NF$2-$NG$2),OR(ND5=$NF$2,NE5=$NG$2)),4,IF(SIGN(ND5-NE5)=SIGN($NF$2-$NG$2),3,IF(OR(ND5=$NF$2,NE5=$NG$2),1,0))))) -> 0 | NJ5: =IF(AND(NH5="",NI5=""),0,IF(AND(NH5=$NJ$2,NI5=$NK$2),5,IF(AND(SIGN(NH5-NI5)=SIGN($NJ$2-$NK$2),OR(NH5=$NJ$2,NI5=$NK$2)),4,IF(SIGN(NH5-NI5)=SIGN($NJ$2-$NK$2),3,IF(OR(NH5=$NJ$2,NI5=$NK$2),1,0))))) -> 0 | NL5: =NB5+NF5+NJ5 -> 0 | NO5: =IF(AND(NM5="",NN5=""),0,IF(AND(NM5=$NO$2,NN5=$NP$2),5,IF(AND(SIGN(NM5-NN5)=SIGN($NO$2-$NP$2),OR(NM5=$NO$2,NN5=$NP$2)),4,IF(SIGN(NM5-NN5)=SIGN($NO$2-$NP$2),3,IF(OR(NM5=$NO$2,NN5=$NP$2),1,0))))) -> 0 | NS5: =IF(AND(NQ5="",NR5=""),0,IF(AND(NQ5=$NS$2,NR5=$NT$2),5,IF(AND(SIGN(NQ5-NR5)=SIGN($NS$2-$NT$2),OR(NQ5=$NS$2,NR5=$NT$2)),4,IF(SIGN(NQ5-NR5)=SIGN($NS$2-$NT$2),3,IF(OR(NQ5=$NS$2,NR5=$NT$2),1,0))))) -> 0 | NU5: =NO5+NS5 -> 0 | NX5: =IF(AND(NV5="",NW5=""),0,IF(AND(NV5=$NX$2,NW5=$NY$2),5,IF(AND(SIGN(NV5-NW5)=SIGN($NX$2-$NY$2),OR(NV5=$NX$2,NW5=$NY$2)),4,IF(SIGN(NV5-NW5)=SIGN($NX$2-$NY$2),3,IF(OR(NV5=$NX$2,NW5=$NY$2),1,0))))) -> 0 | OB5: =IF(AND(NZ5="",OA5=""),0,IF(AND(NZ5=$OB$2,OA5=$OC$2),5,IF(AND(SIGN(NZ5-OA5)=SIGN($OB$2-$OC$2),OR(NZ5=$OB$2,OA5=$OC$2)),4,IF(SIGN(NZ5-OA5)=SIGN($OB$2-$OC$2),3,IF(OR(NZ5=$OB$2,OA5=$OC$2),1,0))))) -> 0 | OD5: =NX5+OB5 -> 0 | OG5: =IF(AND(OE5="",OF5=""),0,IF(AND(OE5=$OG$2,OF5=$OH$2),5,IF(AND(SIGN(OE5-OF5)=SIGN($OG$2-$OH$2),OR(OE5=$OG$2,OF5=$OH$2)),4,IF(SIGN(OE5-OF5)=SIGN($OG$2-$OH$2),3,IF(OR(OE5=$OG$2,OF5=$OH$2),1,0))))) -> 0 | OK5: =IF(AND(OI5="",OJ5=""),0,IF(AND(OI5=$OK$2,OJ5=$OL$2),5,IF(AND(SIGN(OI5-OJ5)=SIGN($OK$2-$OL$2),OR(OI5=$OK$2,OJ5=$OL$2)),4,IF(SIGN(OI5-OJ5)=SIGN($OK$2-$OL$2),3,IF(OR(OI5=$OK$2,OJ5=$OL$2),1,0))))) -> 0 | OM5: =OG5+OK5 -> 0 | OP5: =IF(AND(ON5="",OO5=""),0,IF(AND(ON5=$OP$2,OO5=$OQ$2),5,IF(AND(SIGN(ON5-OO5)=SIGN($OP$2-$OQ$2),OR(ON5=$OP$2,OO5=$OQ$2)),4,IF(SIGN(ON5-OO5)=SIGN($OP$2-$OQ$2),3,IF(OR(ON5=$OP$2,OO5=$OQ$2),1,0))))) -> 0 | OT5: =IF(AND(OR5="",OS5=""),0,IF(AND(OR5=$OT$2,OS5=$OU$2),5,IF(AND(SIGN(OR5-OS5)=SIGN($OT$2-$OU$2),OR(OR5=$OT$2,OS5=$OU$2)),4,IF(SIGN(OR5-OS5)=SIGN($OT$2-$OU$2),3,IF(OR(OR5=$OT$2,OS5=$OU$2),1,0))))) -> 0 | OV5: =OP5+OT5 -> 0 | OY5: =IF(AND(OW5="",OX5=""),0,IF(AND(OW5=$OY$2,OX5=$OZ$2),5,IF(AND(SIGN(OW5-OX5)=SIGN($OY$2-$OZ$2),OR(OW5=$OY$2,OX5=$OZ$2)),4,IF(SIGN(OW5-OX5)=SIGN($OY$2-$OZ$2),3,IF(OR(OW5=$OY$2,OX5=$OZ$2),1,0))))) -> 0 | PA5: =OY5 -> 0 | PD5: =IF(AND(PB5="",PC5=""),0,IF(AND(PB5=$PD$2,PC5=$PE$2),5,IF(AND(SIGN(PB5-PC5)=SIGN($PD$2-$PE$2),OR(PB5=$PD$2,PC5=$PE$2)),4,IF(SIGN(PB5-PC5)=SIGN($PD$2-$PE$2),3,IF(OR(PB5=$PD$2,PC5=$PE$2),1,0))))) -> 0 | PF5: =PD5 -> 0 | PI5: =IF(AND(PG5="",PH5=""),0,IF(AND(PG5=$PI$2,PH5=$PJ$2),5,IF(AND(SIGN(PG5-PH5)=SIGN($PI$2-$PJ$2),OR(PG5=$PI$2,PH5=$PJ$2)),4,IF(SIGN(PG5-PH5)=SIGN($PI$2-$PJ$2),3,IF(OR(PG5=$PI$2,PH5=$PJ$2),1,0))))) -> 0 | PM5: =IF(AND(PK5="",PL5=""),0,IF(AND(PK5=$PM$2,PL5=$PN$2),5,IF(AND(SIGN(PK5-PL5)=SIGN($PM$2-$PN$2),OR(PK5=$PM$2,PL5=$PN$2)),4,IF(SIGN(PK5-PL5)=SIGN($PM$2-$PN$2),3,IF(OR(PK5=$PM$2,PL5=$PN$2),1,0))))) -> 0 | PO5: =PI5+PM5 -> 0 | PR5: =IF(AND(PP5="",PQ5=""),0,IF(AND(PP5=$PR$2,PQ5=$PS$2),5,IF(AND(SIGN(PP5-PQ5)=SIGN($PR$2-$PS$2),OR(PP5=$PR$2,PQ5=$PS$2)),4,IF(SIGN(PP5-PQ5)=SIGN($PR$2-$PS$2),3,IF(OR(PP5=$PR$2,PQ5=$PS$2),1,0))))) -> 0 | PT5: =PR5 -> 0 | PW5: =IF(AND(PU5="",PV5=""),0,IF(AND(PU5=$PW$2,PV5=$PX$2),5,IF(AND(SIGN(PU5-PV5)=SIGN($PW$2-$PX$2),OR(PU5=$PW$2,PV5=$PX$2)),4,IF(SIGN(PU5-PV5)=SIGN($PW$2-$PX$2),3,IF(OR(PU5=$PW$2,PV5=$PX$2),1,0))))) -> 0 | PY5: =PW5 -> 0 | QB5: =IF(AND(PZ5="",QA5=""),0,IF(AND(PZ5=$QB$2,QA5=$QC$2),5,IF(AND(SIGN(PZ5-QA5)=SIGN($QB$2-$QC$2),OR(PZ5=$QB$2,QA5=$QC$2)),4,IF(SIGN(PZ5-QA5)=SIGN($QB$2-$QC$2),3,IF(OR(PZ5=$QB$2,QA5=$QC$2),1,0))))) -> 0 | QD5: =QB5 -> 0 | QG5: =IF(AND(QE5="",QF5=""),0,IF(AND(QE5=$QG$2,QF5=$QH$2),5,IF(AND(SIGN(QE5-QF5)=SIGN($QG$2-$QH$2),OR(QE5=$QG$2,QF5=$QH$2)),4,IF(SIGN(QE5-QF5)=SIGN($QG$2-$QH$2),3,IF(OR(QE5=$QG$2,QF5=$QH$2),1,0))))) -> 0 | QI5: =QG5 -> 0
